<!--

MODEL: Univewrsal Robots UR5 + Robotiq S Model 3 Finger Gripper
AUTHOR: Andrea Franceschetti @IASLAB Research Group
UNIVERSITY: University of Padua
DEPARTMENT: Departement of Information Engineering DEI
Control Engineering / Automation Engineering

-->


<!--Link  MuJoCo modeling: http://www.mujoco.org/book/modeling.html-->

<mujoco model="ur5gripper">
    <compiler angle="radian"
              inertiafromgeom="true"
              texturedir="textures/"
              meshdir="mesh/visual/"/>
    <option timestep="2e-3"
            iterations="100"
            tolerance="1e-10"
            impratio="10"/>
    <!-- <size njmax="600" nconmax="150" nstack="300000"/> -->

    <default>
        <site rgba="0.8 0.6 0.7 0.3" type="ellipsoid" group="3"/>
        <geom contype='1' conaffinity='1' condim='4'  margin="1e-3" solref=".01 1" solimp=".99 .99 .01" />
        <joint armature="0.01" damping=".1"/>
        <default class="UR5">
            <joint damping='65'/>
        </default>
        <default class="UR5e">
            <joint damping='45'/>
        </default>
        <default class="GRIPPER">
            <joint damping='5'/>
        </default>
    <default class="ur5e">
      <material specular="0.5" shininess="0.25"/>
      <joint axis="0 1 0" range="-6.28319 6.28319" armature="0.1"/>
      <general gaintype="fixed" biastype="affine" ctrlrange="-6.2831 6.2831" gainprm="2000" biasprm="0 -2000 -400"
        forcerange="-150 150"/>
      <default class="size3">
        <default class="size3_limited">
          <joint range="-3.1415 3.1415"/>
          <general ctrlrange="-3.1415 3.1415"/>
        </default>
      </default>
      <default class="size1">
        <general gainprm="500" biasprm="0 -500 -100" forcerange="-28 28"/>
      </default>
      <default class="visual">
        <geom type="mesh" contype="0" conaffinity="0" group="2"/>
      </default>
      <default class="collision">
        <geom type="capsule" group="3"/>
        <default class="eef_collision">
          <geom type="cylinder"/>
        </default>
      </default>
      <site size="0.001" rgba="0.5 0.5 0.5 0.3" group="4"/>
    </default>
    </default>

    <visual>
        <map fogstart="3" fogend="5" znear="0.05"/>
        <quality shadowsize="2048"/>
        <scale framelength="0.1"
               framewidth="0.005"
               contactwidth="0.1"
               contactheight="0.005"
               forcewidth="0.01"
               />
    </visual>

    <!--Assets-->
    <asset>
        <material class="ur5e" name="black" rgba="0.033 0.033 0.033 1"/>
    <material class="ur5e" name="jointgray" rgba="0.278 0.278 0.278 1"/>
    <material class="ur5e" name="linkgray" rgba="0.82 0.82 0.82 1"/>
    <material class="ur5e" name="urblue" rgba="0.49 0.678 0.8 1"/>
        <!--Meshes-->
        <mesh name="base"           file="base.stl"     />
        <mesh name="shoulder"       file="shoulder.stl" />
        <mesh name="upperarm"       file="upperarm.stl" />
        <mesh name="forearm"        file="forearm.stl"  />
        <mesh name="wrist1"         file="wrist1.stl"   />
        <mesh name="wrist2"         file="wrist2.stl"   />
        <mesh name="wrist3"         file="wrist3.stl"   />
        <mesh name="gripperpalm"    file="palm.STL"     />
        <mesh name="link_0"         file="link_0.STL"   />
        <mesh name="link_1"         file="link_1.STL"   />
        <mesh name="link_2"         file="link_2.STL"   />
        <mesh name="link_3"         file="link_3.STL"   />

        <mesh name="robotiq_85_base_link_coarse" file="robotiq_85_base_link_coarse.STL" />
        <mesh name="inner_knuckle_coarse" file="inner_knuckle_coarse.STL" />
        <mesh name="inner_finger_coarse" file="inner_finger_coarse.STL" />
        <mesh name="outer_knuckle_coarse" file="outer_knuckle_coarse.STL" />
        <mesh name="outer_finger_coarse" file="outer_finger_coarse.STL" />

        <!--Textures-->
        <texture name="ur5_tex"     type="2d"       builtin="flat" height="32" width="32" rgb1="0.45 0.45 0.45" />
        <texture name="gripper_tex" type="2d"       builtin="flat" height="32" width="32" rgb1="0.45 0.45 0.45" rgb2="0 0 0"/>
        <texture name="bench_tex"   type="2d"       builtin="flat" height="32" width="32" rgb1="0.7 0.7 0.7" />
        <texture name="sky_tex"     type="skybox"   builtin="gradient" width="100" height="100" rgb1="1 1 1" rgb2="0.3 0.3 0.8" />
        <texture name="texgeom"     type="cube"     builtin="flat" mark="cross" width="127" height="1278" rgb1="0.8 0.6 0.4" rgb2="0.8 0.6 0.4" markrgb="1 1 1" random="0.01" />
        <texture name="floor_tex"   type="2d"        builtin="checker" rgb1=".2 .3 .4" rgb2=".1 .2 .3" width="100" height="100" />
        <texture name="wood"        type="cube"     file="wood2.png"/>
        <texture name="metal"        type="cube"     file="metal2.png"/>
        <!--Materials-->
        <material name="ur5_mat"        texture="ur5_tex"   shininess="0.9" specular="0.75" reflectance="0.3"/>
        <material name="gripper_mat"    texture="gripper_tex"   shininess="0.9" specular="0.75" reflectance="0.4"/>
        <material name='floor_mat'      texture="floor_tex"  shininess="0.8" texrepeat="10 10" specular="0.7"  reflectance="0.5" />
        <material name='geom'           texture="texgeom"   texuniform="true" />
        <material name="bench_mat"      texture="metal"   shininess="0.1" specular="0.5" reflectance="0.2"/>
        <material name="tablecube"      texture="wood" rgba=".8 .8 .8 1"/>
    </asset>

    <!--Contacts-->
    <contact>
        <exclude body1="box_link" body2="base_link"/>
        <exclude body1="base_link" body2="shoulder_link"/>
        <exclude body1="shoulder_link" body2="upper_arm_link"/>
        <exclude body1="upper_arm_link" body2="forearm_link"/>
        <exclude body1="forearm_link" body2="wrist_1_link"/>
        <exclude body1="wrist_1_link" body2="wrist_2_link"/>
        <exclude body1="wrist_2_link" body2="wrist_3_link"/>
        <exclude body1="ee_link" body2="wrist_3_link"/>
    </contact>


    <!--MODEL DESCRIPTION-->
    <worldbody>
        
        <!--Robot UR5-->
        <body name="box_link" pos="0 0 0">
            <!--<geom size=".3 .2 .435" type="box" material="bench_mat"/>-->
            <inertial pos="0 0 0" mass="1000" diaginertia="0 0 0" />
            <body name="base_link" pos="0 0 0">
                <inertial pos="0 0 0" quat="0.5 0.5 -0.5 0.5" mass="4" diaginertia="0.0072 0.00443333 0.00443333" />
                <geom type="mesh"  mesh="base" material="ur5_mat"/>
                <body name="shoulder_link" pos="0 0 0.089159">
                    <inertial pos="0 0 0" mass="3.7" diaginertia="0.0102675 0.0102675 0.00666" />
                    <joint name="ur5_joint1" class="size3" pos="0 0 0" axis="0 0 1" />
                    <geom type="mesh"  mesh="shoulder" material="ur5_mat"/>
                    <body name="upper_arm_link" pos="0 0.13585 0" quat="0.707107 0 0.707107 0">
                        <inertial pos="0 0 0.28" mass="8.393" diaginertia="0.226891 0.226891 0.0151074" />
                        <joint name="ur5_joint2" class="size3" pos="0 0 0" axis="0 1 0" /> <!--Range= -3.14159 3.14159-->
                        <geom type="mesh"  mesh="upperarm" material="ur5_mat"/>
                        <body name="forearm_link" pos="0 -0.1197 0.425">
                            <inertial pos="0 0 0.25" mass="2.275" diaginertia="0.0494433 0.0494433 0.004095" />
                            <joint name="ur5_joint3" class="size3_limited" pos="0 0 0" axis="0 1 0"/>
                            <geom type="mesh"  mesh="forearm" material="ur5_mat"/>
                            <body name="wrist_1_link" pos="0 0 0.39225" quat="0.707107 0 0.707107 0">
                                <inertial pos="0 0 0" quat="0.5 0.5 -0.5 0.5" mass="1.219" diaginertia="0.21942 0.111173 0.111173" />
                                <joint name="ur5_joint4" class="size1" pos="0 0 0" axis="0 1 0" />
                                <geom type="mesh"  mesh="wrist1" material="ur5_mat"/>
                                <body name="wrist_2_link" pos="0 0.093 0">
                                    <inertial pos="0 0 0" quat="0.5 0.5 -0.5 0.5" mass="1.219" diaginertia="0.21942 0.111173 0.111173" />
                                    <joint name="ur5_joint5" class="size1" pos="0 0 0" axis="0 0 1"  />
                                    <geom type="mesh"  mesh="wrist2" material="ur5_mat"/>
                                    <body name="wrist_3_link" pos="0 0 0.09465">
                                        <inertial pos="0 0 0" quat="0.5 0.5 -0.5 0.5" mass="0.1879" diaginertia="0.033822 0.0171365 0.0171365" />
                                        
                                        <joint name="ur5_joint6" class="size1" pos="0 0 0" axis="0 1 0" />
                                        <geom type="mesh"  mesh="wrist3" material="ur5_mat"/>
                                        <body name="ee_link" pos="0 0.0823 0" quat="0.707107 0 0 0.707107">
                                            <inertial pos="-0.01 0 0" mass="0.001" diaginertia="1.66667e-08 1.66667e-08 1.66667e-08" />
                                            <geom size="0.005 0.005 0.005" pos="-0.01 0 0" type="box" />
                                        <!--GRIPPER-->
                                             <!-- <joint name="ee_to_base" pos="0 0 0" axis="1 0 0" limited="true" range="0 0" /> -->
                                            <body name="robotiq_85_base_link" pos="0 0 0" quat="0.5 0.5 0.5 0.5 ">
                                            <inertial pos="0.00021987 -2.3546e-10 0.030163"  quat="0.707058 0.00723369 0.00723345 0.707081" mass="0.30915" diaginertia="0.00030737 0.000289758 0.000199102" />
                                            <geom type="mesh" rgba="0.1 0.1 0.1 1" friction="0.8 0.8 0.8" mesh="robotiq_85_base_link_coarse" />
                                            <camera name="ee_camera" pos="0 0 0.05" quat="0 1 0 0" fovy="60" mode="fixed"/>
                                            <body name="left_inner_knuckle" pos="0.0127 0 0.0693075">
                                                <inertial pos="0.0170975 -3.93809e-10 0.0224918"   quat="0.947655 0 -0.319297 0" mass="0.0110931" diaginertia="5.59353e-06 3.96549e-06 1.88108e-06" />
                                                <geom type="mesh" rgba="0.1 0.1 0.1 1" friction="0.8 0.8 0.8" mesh="inner_knuckle_coarse" />
                                                 <joint name="base_to_lik" class="GRIPPER" pos="0 0 0" axis="0 1 0" limited="true" range="-1 1" />
                                                <body name="left_inner_finger" pos="0.0345853 0 0.045497" >
                                                    <inertial pos="0.00602756 0 0.00669926"  quat="0.699065 0.106339 0.106339 0.699065" mass="0.00724255" diaginertia="1.70064e-06 1.58577e-06 3.69621e-07" />
                                                    <geom type="mesh" rgba="0.1 0.1 0.1 1" friction="0.8 0.8 0.8" mesh="inner_finger_coarse" />
                                                </body>
                                            </body>
                                            <body name="right_inner_knuckle" pos="-0.0127 0 0.0693075" quat="0 0 0 1">
                                                <inertial pos="0.0168606 3.93808e-10 0.02267"  quat="0.949317 0 -0.314322 0" mass="0.0110931" diaginertia="5.59353e-06 3.96549e-06 1.88108e-06" />
                                                <geom type="mesh" rgba="0.1 0.1 0.1 1" friction="0.8 0.8 0.8" mesh="inner_knuckle_coarse" />
                                                <joint name="base_to_rik" class="GRIPPER" pos="0 0 0" axis="0 1 0" limited="true" range="-1 1" />

                                                <body name="right_inner_finger" pos="0.034106 0 0.0458574">
                                                    <inertial pos="0.00602756 0 0.00669926"  quat="0.699065 0.106339 0.106339 0.699065" mass="0.00724255" diaginertia="1.70064e-06 1.58577e-06 3.69621e-07" />
                                                    <geom type="mesh" rgba="0.1 0.1 0.1 1" friction="0.8 0.8 0.8" mesh="inner_finger_coarse" />
                                                </body>
                                            </body>
                                    </body>
                                </body>
                            </body>
                        </body>
                    </body>
                </body>
            </body>
        </body>
    </body>
                <body name="base" pos="0 0 0" quat="1.7949e-09 0 0 -1">
                    <inertial pos="0 0 0" quat="1.7949e-09 0 0 -1" mass="0" diaginertia="0 0 0" />
                </body>
        </body>
    </worldbody>

    <equality>
        <joint name="fingers" joint1="base_to_rik" joint2="base_to_lik" polycoef="0 1 0 0 0"/>
    </equality>


    <!--ACTUATORS-->
    <actuator>
        <general class="size3" name="ur5_joint1" joint="ur5_joint1"/>
    <general class="size3" name="ur5_joint2" joint="ur5_joint2"/>
    <general class="size3_limited" name="ur5_joint3" joint="ur5_joint3"/>
    <general class="size1" name="ur5_joint4" joint="ur5_joint4"/>
    <general class="size1" name="ur5_joint5" joint="ur5_joint5"/>
    <general class="size1" name="ur5_joint6" joint="ur5_joint6"/>
        <general name='gripper_motor' ctrllimited="true" ctrlrange="-1 1" joint='base_to_lik' gear="101"/>        
    </actuator>
</mujoco>
