<mujoco model="scene">
  <compiler angle="radian"/>

  <option timestep="0.005" impratio="10" integrator="implicitfast" cone="elliptic" solver="PGS"/>

  <visual>
    <global azimuth="210" elevation="-35" offwidth="1280" offheight="1280"/>
    <headlight diffuse="0.6 0.6 0.6" specular="0 0 0"/>
    <rgba haze="0.15 0.25 0.35 1"/>
  </visual>

  <statistic meansize="0.08" extent="0.8" center="1.8 1.1 1.7"/>

  <default>
    <default class="ur5e">
      <material shininess="0.25"/>
      <joint range="-6.28319 6.28319" armature="0.1"/>
      <site size="0.001 0.005 0.005" group="4" rgba="0.5 0.5 0.5 0.3"/>
      <general ctrlrange="-6.2831 6.2831" forcerange="-150 150" biastype="affine" gainprm="2000" biasprm="0 -2000 -400"/>
      <default class="size3">
        <default class="size3_limited">
          <joint range="-3.1415 3.1415"/>
          <general ctrlrange="-3.1415 3.1415"/>
        </default>
      </default>
      <default class="size1">
        <general forcerange="-28 28" gainprm="500" biasprm="0 -500 -100"/>
      </default>
      <default class="visual">
        <geom type="mesh" contype="0" conaffinity="0" group="2"/>
      </default>
      <default class="collision">
        <geom type="capsule" group="3"/>
        <default class="eef_collision">
          <geom type="cylinder"/>
        </default>
      </default>
    </default>
    <default class="2f85">
      <mesh scale="0.001 0.001 0.001"/>
      <general biastype="affine"/>
      <joint axis="1 0 0"/>
      <default class="driver">
        <joint solreflimit="0.005 1" solimplimit="0.95 0.99 0.001" range="0 0.8" armature="0.005" damping="0.1"/>
      </default>
      <default class="follower">
        <joint solreflimit="0.005 1" solimplimit="0.95 0.99 0.001" range="-0.872664 0.872664" armature="0.001" pos="0 -0.018 0.0065"/>
      </default>
      <default class="spring_link">
        <joint springref="2.62" stiffness="0.05" range="-0.29670597283 0.8" armature="0.001" damping="0.00125"/>
      </default>
      <default class="coupler">
        <joint solreflimit="0.005 1" solimplimit="0.95 0.99 0.001" range="-1.57 0" armature="0.001"/>
      </default>
      <default class="visual2">
        <geom type="mesh" contype="0" conaffinity="0" group="2"/>
      </default>
      <default class="collision2">
        <geom type="mesh" group="3"/>
        <default class="pad_box1">
          <geom mass="0" pos="0 -0.0026 0.028125" size="0.011 0.004 0.009375" type="box" priority="1" friction="0.7" solref="0.004 1" solimp="0.95 0.99 0.001" rgba="0.55 0.55 0.55 1"/>
        </default>
        <default class="pad_box2">
          <geom mass="0" pos="0 -0.0026 0.009375" size="0.011 0.004 0.009375" type="box" priority="1" friction="0.6" solref="0.004 1" solimp="0.95 0.99 0.001" rgba="0.45 0.45 0.45 1"/>
        </default>
      </default>
    </default>
  </default>

  <asset>
    <texture type="skybox" colorspace="auto" builtin="gradient" rgb1="0.3 0.5 0.7" rgb2="0 0 0" width="512" height="3072"/>
    <texture type="2d" colorspace="auto" name="groundplane" builtin="checker" mark="edge" rgb1="0.2 0.3 0.4" rgb2="0.1 0.2 0.3" markrgb="0.8 0.8 0.8" width="300" height="300"/>
    <texture type="2d" colorspace="linear" name="apple_tex" file="../assets/fruit/mesh/red-apple.png"/>
    <texture type="2d" colorspace="linear" name="banana_tex" file="../assets/fruit/mesh/yellow-banana.png"/>
    <material name="black" rgba="0.033 0.033 0.033 1"/>
    <material name="jointgray" rgba="0.278 0.278 0.278 1"/>
    <material name="linkgray" rgba="0.82 0.82 0.82 1"/>
    <material name="urblue" rgba="0.49 0.678 0.8 1"/>
    <material name="metal" rgba="0.58 0.58 0.58 1"/>
    <material name="silicone" rgba="0.1882 0.1882 0.1882 1"/>
    <material name="gray" rgba="0.4627 0.4627 0.4627 1"/>
    <material name="groundplane" texture="groundplane" texuniform="true" texrepeat="5 5" reflectance="0.2"/>
    <material name="apple_mat" texture="apple_tex"/>
    <material name="banana_mat" texture="banana_tex"/>
    <mesh name="base_0" file="/home/lt/malanxuan/yolo-sam-mlx/ur5e_mujoco/assets/universal_robots_ur5e/assets/base_0.obj"/>
    <mesh name="base_1" file="/home/lt/malanxuan/yolo-sam-mlx/ur5e_mujoco/assets/universal_robots_ur5e/assets/base_1.obj"/>
    <mesh name="shoulder_0" file="/home/lt/malanxuan/yolo-sam-mlx/ur5e_mujoco/assets/universal_robots_ur5e/assets/shoulder_0.obj"/>
    <mesh name="shoulder_1" file="/home/lt/malanxuan/yolo-sam-mlx/ur5e_mujoco/assets/universal_robots_ur5e/assets/shoulder_1.obj"/>
    <mesh name="shoulder_2" file="/home/lt/malanxuan/yolo-sam-mlx/ur5e_mujoco/assets/universal_robots_ur5e/assets/shoulder_2.obj"/>
    <mesh name="upperarm_0" file="/home/lt/malanxuan/yolo-sam-mlx/ur5e_mujoco/assets/universal_robots_ur5e/assets/upperarm_0.obj"/>
    <mesh name="upperarm_1" file="/home/lt/malanxuan/yolo-sam-mlx/ur5e_mujoco/assets/universal_robots_ur5e/assets/upperarm_1.obj"/>
    <mesh name="upperarm_2" file="/home/lt/malanxuan/yolo-sam-mlx/ur5e_mujoco/assets/universal_robots_ur5e/assets/upperarm_2.obj"/>
    <mesh name="upperarm_3" file="/home/lt/malanxuan/yolo-sam-mlx/ur5e_mujoco/assets/universal_robots_ur5e/assets/upperarm_3.obj"/>
    <mesh name="forearm_0" file="/home/lt/malanxuan/yolo-sam-mlx/ur5e_mujoco/assets/universal_robots_ur5e/assets/forearm_0.obj"/>
    <mesh name="forearm_1" file="/home/lt/malanxuan/yolo-sam-mlx/ur5e_mujoco/assets/universal_robots_ur5e/assets/forearm_1.obj"/>
    <mesh name="forearm_2" file="/home/lt/malanxuan/yolo-sam-mlx/ur5e_mujoco/assets/universal_robots_ur5e/assets/forearm_2.obj"/>
    <mesh name="forearm_3" file="/home/lt/malanxuan/yolo-sam-mlx/ur5e_mujoco/assets/universal_robots_ur5e/assets/forearm_3.obj"/>
    <mesh name="wrist1_0" file="/home/lt/malanxuan/yolo-sam-mlx/ur5e_mujoco/assets/universal_robots_ur5e/assets/wrist1_0.obj"/>
    <mesh name="wrist1_1" file="/home/lt/malanxuan/yolo-sam-mlx/ur5e_mujoco/assets/universal_robots_ur5e/assets/wrist1_1.obj"/>
    <mesh name="wrist1_2" file="/home/lt/malanxuan/yolo-sam-mlx/ur5e_mujoco/assets/universal_robots_ur5e/assets/wrist1_2.obj"/>
    <mesh name="wrist2_0" file="/home/lt/malanxuan/yolo-sam-mlx/ur5e_mujoco/assets/universal_robots_ur5e/assets/wrist2_0.obj"/>
    <mesh name="wrist2_1" file="/home/lt/malanxuan/yolo-sam-mlx/ur5e_mujoco/assets/universal_robots_ur5e/assets/wrist2_1.obj"/>
    <mesh name="wrist2_2" file="/home/lt/malanxuan/yolo-sam-mlx/ur5e_mujoco/assets/universal_robots_ur5e/assets/wrist2_2.obj"/>
    <mesh name="wrist3" file="/home/lt/malanxuan/yolo-sam-mlx/ur5e_mujoco/assets/universal_robots_ur5e/assets/wrist3.obj"/>
    <mesh name="base_mount" class="2f85" file="/home/lt/malanxuan/yolo-sam-mlx/ur5e_mujoco/assets/robotiq_2f85/assets/base_mount.stl"/>
    <mesh name="base" class="2f85" file="/home/lt/malanxuan/yolo-sam-mlx/ur5e_mujoco/assets/robotiq_2f85/assets/base.stl"/>
    <mesh name="driver" class="2f85" file="/home/lt/malanxuan/yolo-sam-mlx/ur5e_mujoco/assets/robotiq_2f85/assets/driver.stl"/>
    <mesh name="coupler" class="2f85" file="/home/lt/malanxuan/yolo-sam-mlx/ur5e_mujoco/assets/robotiq_2f85/assets/coupler.stl"/>
    <mesh name="follower" class="2f85" file="/home/lt/malanxuan/yolo-sam-mlx/ur5e_mujoco/assets/robotiq_2f85/assets/follower.stl"/>
    <mesh name="pad" class="2f85" file="/home/lt/malanxuan/yolo-sam-mlx/ur5e_mujoco/assets/robotiq_2f85/assets/pad.stl"/>
    <mesh name="silicone_pad" class="2f85" file="/home/lt/malanxuan/yolo-sam-mlx/ur5e_mujoco/assets/robotiq_2f85/assets/silicone_pad.stl"/>
    <mesh name="spring_link" class="2f85" file="/home/lt/malanxuan/yolo-sam-mlx/ur5e_mujoco/assets/robotiq_2f85/assets/spring_link.stl"/>
    <mesh name="table" file="../assets/table/sigmund_table.stl"/>
    <mesh name="apple" content_type="model/stl" file="/home/lt/malanxuan/yolo-sam-mlx/ur5e_mujoco/assets/fruit/stl/apple.stl" scale="0.705 0.705 0.705"/>
  </asset>

  <worldbody>
    <geom name="floor" size="0 0 0.05" type="plane" material="groundplane"/>
    <geom name="x-aixs" size="0.01 0.5" pos="0.5 0 0" quat="0.707107 0 -0.707107 0" type="cylinder" contype="0" conaffinity="0" group="2" rgba="1 0 0 1"/>
    <geom name="y-aixs" size="0.01 0.5" pos="0 0.5 0" quat="0.707107 0.707107 0 0" type="cylinder" contype="0" conaffinity="0" group="2" rgba="0 1 0 1"/>
    <geom name="z-aixs" size="0.01 0.5" pos="0 0 0.5" quat="0 1 0 0" type="cylinder" contype="0" conaffinity="0" group="2" rgba="0 0 1 1"/>
    <camera name="cam" pos="0.05 0 1.2" quat="0.688191 0.16246 -0.16246 -0.688191"/>
    <camera name="cam1" pos="1.2 -0.94 0.27" quat="0.65986 0.672787 0.238867 0.234277"/>
    <camera name="cam2" pos="2.25757 -0.0909521 0.327685" quat="0.487356 0.512332 0.512332 0.487356"/>
    <light name="spotlight" target="wrist_2_link" pos="0 -1 2" dir="0 0 -1" mode="targetbodycom"/>
    <light pos="1.3 0.7 2.5" dir="0 0 -1" type="directional"/>
    <body name="ur5e_base" childclass="ur5e">
      <inertial pos="0 0 0" mass="4" diaginertia="0.00443333 0.00443333 0.0072"/>
      <geom class="visual" material="black" mesh="base_0"/>
      <geom class="visual" material="jointgray" mesh="base_1"/>
      <body name="shoulder_link" pos="0 0 0.163">
        <inertial pos="0 0 0" mass="3.7" diaginertia="0.0102675 0.0102675 0.00666"/>
        <joint name="shoulder_pan_joint" class="size3" pos="0 0 0" axis="0 0 1"/>
        <geom class="visual" material="urblue" mesh="shoulder_0"/>
        <geom class="visual" material="black" mesh="shoulder_1"/>
        <geom class="visual" material="jointgray" mesh="shoulder_2"/>
        <geom class="collision" size="0.06 0.06" pos="0 0 -0.04"/>
        <body name="upper_arm_link" pos="0 0.138 0">
          <inertial pos="0 0 0.2125" mass="8.393" diaginertia="0.133886 0.133886 0.0151074"/>
          <joint name="shoulder_lift_joint" class="size3" pos="0 0 0" axis="0 1 0"/>
          <geom class="visual" material="linkgray" mesh="upperarm_0"/>
          <geom class="visual" material="black" mesh="upperarm_1"/>
          <geom class="visual" material="jointgray" mesh="upperarm_2"/>
          <geom class="visual" material="urblue" mesh="upperarm_3"/>
          <geom class="collision" size="0.06 0.06" pos="0 -0.04 0" quat="0.707107 0.707107 0 0"/>
          <geom class="collision" size="0.05 0.2" pos="0 0 0.2"/>
          <body name="forearm_link" pos="0 -0.131 0.425">
            <inertial pos="0 0 0.196" mass="2.275" diaginertia="0.0311796 0.0311796 0.004095"/>
            <joint name="elbow_joint" class="size3_limited" pos="0 0 0" axis="0 1 0"/>
            <geom class="visual" material="urblue" mesh="forearm_0"/>
            <geom class="visual" material="linkgray" mesh="forearm_1"/>
            <geom class="visual" material="black" mesh="forearm_2"/>
            <geom class="visual" material="jointgray" mesh="forearm_3"/>
            <geom class="collision" size="0.055 0.06" pos="0 0.08 0" quat="0.707107 0.707107 0 0"/>
            <geom class="collision" size="0.038 0.19" pos="0 0 0.2"/>
            <body name="wrist_1_link" pos="0 0 0.392">
              <inertial pos="0 0.127 0" mass="1.219" diaginertia="0.0025599 0.0025599 0.0021942"/>
              <joint name="wrist_1_joint" class="size1" pos="0 0 0" axis="0 1 0"/>
              <geom class="visual" material="black" mesh="wrist1_0"/>
              <geom class="visual" material="urblue" mesh="wrist1_1"/>
              <geom class="visual" material="jointgray" mesh="wrist1_2"/>
              <geom class="collision" size="0.04 0.07" pos="0 0.05 0" quat="0.707107 0.707107 0 0"/>
              <body name="wrist_2_link" pos="0 0.127 0">
                <inertial pos="0 0 0.1" mass="1.219" diaginertia="0.0025599 0.0025599 0.0021942"/>
                <joint name="wrist_2_joint" class="size1" pos="0 0 0" axis="0 0 1"/>
                <geom class="visual" material="black" mesh="wrist2_0"/>
                <geom class="visual" material="urblue" mesh="wrist2_1"/>
                <geom class="visual" material="jointgray" mesh="wrist2_2"/>
                <geom class="collision" size="0.04 0.06" pos="0 0 0.04"/>
                <geom class="collision" size="0.04 0.04" pos="0 0.02 0.1" quat="0.707107 0.707107 0 0"/>
                <body name="wrist_3_link" pos="0 0 0.1">
                  <inertial pos="0 0.0771683 0" quat="0.707107 0 0 0.707107" mass="0.1889" diaginertia="0.000132134 9.90863e-05 9.90863e-05"/>
                  <joint name="wrist_3_joint" class="size1" pos="0 0 0" axis="0 1 0"/>
                  <geom class="visual" material="linkgray" mesh="wrist3"/>
                  <body name="flange" pos="0 0.1 0" quat="0.707107 -0.707107 0 0">
                    <site name="tcp" pos="0 0 0" size="0.01" group="2" rgba="0 1 0 0.5"/>
                    <camera name="ee_camera" pos="0 0 0.1" quat="0 1 0 0" fovy="60"/>
                  </body>
                </body>
              </body>
            </body>
          </body>
        </body>
      </body>
    </body>
    <body name="2f85_base" childclass="2f85" pos="0 0 0.007">
      <joint name="2f85" type="free"/>
      <geom class="visual2" material="black" mesh="base_mount"/>
      <geom class="collision2" mesh="base_mount"/>
      <body name="base" pos="0 0 0.0038" quat="0.707107 0 0 -0.707107">
        <inertial pos="0 -2.70394e-05 0.0354675" quat="0.999999 -0.00152849 0 0" mass="0.777441" diaginertia="0.000260285 0.000225381 0.000152708"/>
        <geom class="visual2" material="black" mesh="base"/>
        <geom class="collision2" mesh="base"/>
        <site name="pinch" pos="0 0 0.145" group="5" rgba="0.9 0.9 0.9 1"/>
        <body name="right_driver" pos="0 0.0306011 0.054904">
          <inertial pos="2.96931e-12 0.0177547 0.00107314" quat="0.681301 0.732003 0 0" mass="0.00899563" diaginertia="1.72352e-06 1.60906e-06 3.22006e-07"/>
          <joint name="right_driver_joint" class="driver" pos="0 0 0" axis="1 0 0"/>
          <geom class="visual2" material="gray" mesh="driver"/>
          <geom class="collision2" mesh="driver"/>
          <body name="right_coupler" pos="0 0.0315 -0.0041">
            <inertial pos="0 0.00301209 0.0232175" quat="0.705636 -0.0455904 0.0455904 0.705636" mass="0.0140974" diaginertia="4.16206e-06 3.52216e-06 8.88131e-07"/>
            <joint name="right_coupler_joint" class="coupler" pos="0 0 0" axis="1 0 0"/>
            <geom class="visual2" material="black" mesh="coupler"/>
            <geom class="collision2" mesh="coupler"/>
          </body>
        </body>
        <body name="right_spring_link" pos="0 0.0132 0.0609">
          <inertial pos="-8.65005e-09 0.0181624 0.0212658" quat="0.663403 -0.244737 0.244737 0.663403" mass="0.0221642" diaginertia="8.96853e-06 6.71733e-06 2.63931e-06"/>
          <joint name="right_spring_link_joint" class="spring_link" pos="0 0 0" axis="1 0 0" springref="2.62"/>
          <geom class="visual2" material="black" mesh="spring_link"/>
          <geom class="collision2" mesh="spring_link"/>
          <body name="right_follower" pos="0 0.055 0.0375">
            <inertial pos="0 -0.011046 0.0124786" quat="0.986437 0.164143 0 0" mass="0.0125222" diaginertia="2.67415e-06 2.4559e-06 6.02031e-07"/>
            <joint name="right_follower_joint" class="follower" pos="0 -0.018 0.0065" axis="1 0 0"/>
            <geom class="visual2" material="black" mesh="follower"/>
            <geom class="collision2" mesh="follower"/>
            <body name="right_pad" pos="0 -0.0189 0.01352">
              <inertial pos="0 -0.0025 0.0185" quat="0.707107 0 0 0.707107" mass="0.0035" diaginertia="4.73958e-07 3.64583e-07 1.23958e-07"/>
              <geom name="right_pad1" class="pad_box1" pos="0 -0.0026 0.028125" mass="0"/>
              <geom name="right_pad2" class="pad_box2" pos="0 -0.0026 0.009375" mass="0"/>
              <geom class="visual2" mesh="pad"/>
              <body name="right_silicone_pad">
                <geom class="visual2" material="black" mesh="silicone_pad"/>
              </body>
            </body>
          </body>
        </body>
        <body name="left_driver" pos="0 -0.0306011 0.054904" quat="0 0 0 1">
          <inertial pos="0 0.0177547 0.00107314" quat="0.681301 0.732003 0 0" mass="0.00899563" diaginertia="1.72352e-06 1.60906e-06 3.22006e-07"/>
          <joint name="left_driver_joint" class="driver" pos="0 0 0" axis="1 0 0"/>
          <geom class="visual2" material="gray" mesh="driver"/>
          <geom class="collision2" mesh="driver"/>
          <body name="left_coupler" pos="0 0.0315 -0.0041">
            <inertial pos="0 0.00301209 0.0232175" quat="0.705636 -0.0455904 0.0455904 0.705636" mass="0.0140974" diaginertia="4.16206e-06 3.52216e-06 8.88131e-07"/>
            <joint name="left_coupler_joint" class="coupler" pos="0 0 0" axis="1 0 0"/>
            <geom class="visual2" material="black" mesh="coupler"/>
            <geom class="collision2" mesh="coupler"/>
          </body>
        </body>
        <body name="left_spring_link" pos="0 -0.0132 0.0609" quat="0 0 0 1">
          <inertial pos="-8.65005e-09 0.0181624 0.0212658" quat="0.663403 -0.244737 0.244737 0.663403" mass="0.0221642" diaginertia="8.96853e-06 6.71733e-06 2.63931e-06"/>
          <joint name="left_spring_link_joint" class="spring_link" pos="0 0 0" axis="1 0 0" springref="2.62"/>
          <geom class="visual2" material="black" mesh="spring_link"/>
          <geom class="collision2" mesh="spring_link"/>
          <body name="left_follower" pos="0 0.055 0.0375">
            <inertial pos="0 -0.011046 0.0124786" quat="0.986437 0.164143 0 0" mass="0.0125222" diaginertia="2.67415e-06 2.4559e-06 6.02031e-07"/>
            <joint name="left_follower_joint" class="follower" pos="0 -0.018 0.0065" axis="1 0 0"/>
            <geom class="visual2" material="black" mesh="follower"/>
            <geom class="collision2" mesh="follower"/>
            <body name="left_pad" pos="0 -0.0189 0.01352">
              <inertial pos="0 -0.0025 0.0185" quat="0.707107 0 0 0.707107" mass="0.0035" diaginertia="4.73958e-07 3.64583e-07 1.23958e-07"/>
              <geom name="left_pad1" class="pad_box1" pos="0 -0.0026 0.028125" mass="0"/>
              <geom name="left_pad2" class="pad_box2" pos="0 -0.0026 0.009375" mass="0"/>
              <geom class="visual2" mesh="pad"/>
              <body name="left_silicone_pad">
                <geom class="visual2" material="black" mesh="silicone_pad"/>
              </body>
            </body>
          </body>
        </body>
      </body>
    </body>
    <body name="mocap" pos="0.8 0.6 0.74" mocap="true">
      <geom name="mocap" size="1e-06"/>
    </body>
    <body name="plate" pos="0.4 0.4 0.04">
      <geom name="plate_geom" size="0.08 0.008" type="cylinder" rgba="0.92 0.88 0.82 1"/>
    </body>
    <body name="apple0" pos="0.560126 0.299633 0.041" quat="-0.687132 0.687132 0.166882 -0.166882">
      <joint name="apple0_joint" type="free" damping="0.1"/>
      <geom name="apple0" type="mesh" material="apple_mat" mesh="apple"/>
    </body>
  </worldbody>

  <contact>
    <exclude body1="wrist_2_link" body2="2f85_base"/>
    <exclude body1="wrist_3_link" body2="2f85_base"/>
    <exclude body1="flange" body2="2f85_base"/>
    <exclude body1="base" body2="right_driver"/>
    <exclude body1="base" body2="right_spring_link"/>
    <exclude body1="base" body2="left_driver"/>
    <exclude body1="base" body2="left_spring_link"/>
    <exclude body1="right_coupler" body2="right_follower"/>
    <exclude body1="left_coupler" body2="left_follower"/>
  </contact>

  <equality>
    <connect body1="right_follower" body2="right_coupler" anchor="0 0 0" solref="0.005 1" solimp="0.95 0.99 0.001"/>
    <connect body1="left_follower" body2="left_coupler" anchor="0 0 0" solref="0.005 1" solimp="0.95 0.99 0.001"/>
    <joint joint1="right_driver_joint" joint2="left_driver_joint" polycoef="0 1 0 0 0" solref="0.005 1" solimp="0.95 0.99 0.001"/>
    <weld name="attach" body1="flange" body2="2f85_base" anchor="0 0 0" relpose="0 0 0 0 0 0 0" torquescale="1" active="false"/>
    <weld name="attach_mocap" body1="mocap" body2="ur5e_base" anchor="0 0 0" relpose="0 0 0 0 0 0 0" torquescale="1" active="false"/>
  </equality>

  <tendon>
    <fixed name="split">
      <joint joint="right_driver_joint" coef="0.5"/>
      <joint joint="left_driver_joint" coef="0.5"/>
    </fixed>
  </tendon>

  <actuator>
    <general name="shoulder_pan" class="size3" joint="shoulder_pan_joint"/>
    <general name="shoulder_lift" class="size3" joint="shoulder_lift_joint"/>
    <general name="elbow" class="size3_limited" joint="elbow_joint"/>
    <general name="wrist_1" class="size1" joint="wrist_1_joint"/>
    <general name="wrist_2" class="size1" joint="wrist_2_joint"/>
    <general name="wrist_3" class="size1" joint="wrist_3_joint"/>
    <general name="fingers_actuator" class="2f85" tendon="split" ctrlrange="0 255" forcerange="-5 5" gainprm="0.3137255 0 0" biasprm="0 -100 -10"/>
  </actuator>
</mujoco>
