<mujoco model="r1_pro_with_hand">
  <compiler angle="radian" meshdir="/home/mlx/mujoco/YOLO_World-SAM-GraspNet/URDF_r1_pro_with_hand/meshes/"/>

  <asset>
    <mesh name="base_link" file="base_link.STL"/>
    <mesh name="steer_motor_link1" file="steer_motor_link1.STL"/>
    <mesh name="wheel_motor_link1" file="wheel_motor_link1.STL"/>
    <mesh name="steer_motor_link2" file="steer_motor_link2.STL"/>
    <mesh name="wheel_motor_link2" file="wheel_motor_link2.STL"/>
    <mesh name="steer_motor_link3" file="steer_motor_link3.STL"/>
    <mesh name="wheel_motor_link3" file="wheel_motor_link3.STL"/>
    <mesh name="torso_link1" file="torso_link1.STL"/>
    <mesh name="torso_link2" file="torso_link2.STL"/>
    <mesh name="torso_link3" file="torso_link3.STL"/>
    <mesh name="torso_link4" file="torso_link4.STL"/>
    <mesh name="zed_link" file="zed_link.STL"/>
    <mesh name="left_arm_base_link" file="left_arm_base_link.STL"/>
    <mesh name="left_arm_link1" file="left_arm_link1.STL"/>
    <mesh name="left_arm_link2" file="left_arm_link2.STL"/>
    <mesh name="left_arm_link3" file="left_arm_link3.STL"/>
    <mesh name="left_arm_link4" file="left_arm_link4.STL"/>
    <mesh name="left_arm_link5" file="left_arm_link5.STL"/>
    <mesh name="left_arm_link6" file="left_arm_link6.STL"/>
    <mesh name="left_arm_link7" file="left_arm_link7.STL"/>
    <mesh name="L_hand_base_link" file="L_hand_base_link.STL"/>
    <mesh name="L_hand_palm_link" file="L_hand_palm_link.STL"/>
    <mesh name="L_thumb_proximal_base" file="L_thumb_proximal_base.STL"/>
    <mesh name="L_thumb_proximal" file="L_thumb_proximal.STL"/>
    <mesh name="L_thumb_intermediate" file="L_thumb_intermediate.STL"/>
    <mesh name="L_thumb_distal" file="L_thumb_distal.STL"/>
    <mesh name="L_index_proximal" file="L_index_proximal.STL"/>
    <mesh name="L_index_distal" file="L_index_distal.STL"/>
    <mesh name="L_middle_proximal" file="L_middle_proximal.STL"/>
    <mesh name="L_middle_distal" file="L_middle_distal.STL"/>
    <mesh name="L_ring_proximal" file="L_ring_proximal.STL"/>
    <mesh name="L_ring_distal" file="L_ring_distal.STL"/>
    <mesh name="L_pinky_proximal" file="L_pinky_proximal.STL"/>
    <mesh name="L_pinky_distal" file="L_pinky_distal.STL"/>
    <mesh name="right_arm_base_link" file="right_arm_base_link.STL"/>
    <mesh name="right_arm_link1" file="right_arm_link1.STL"/>
    <mesh name="right_arm_link2" file="right_arm_link2.STL"/>
    <mesh name="right_arm_link3" file="right_arm_link3.STL"/>
    <mesh name="right_arm_link4" file="right_arm_link4.STL"/>
    <mesh name="right_arm_link5" file="right_arm_link5.STL"/>
    <mesh name="right_arm_link6" file="right_arm_link6.STL"/>
    <mesh name="right_arm_link7" file="right_arm_link7.STL"/>
    <mesh name="R_hand_base_link" file="R_hand_base_link.STL"/>
    <mesh name="R_hand_palm_link" file="R_hand_palm_link.STL"/>
    <mesh name="R_thumb_proximal_base" file="R_thumb_proximal_base.STL"/>
    <mesh name="R_thumb_proximal" file="R_thumb_proximal.STL"/>
    <mesh name="R_thumb_intermediate" file="R_thumb_intermediate.STL"/>
    <mesh name="R_thumb_distal" file="R_thumb_distal.STL"/>
    <mesh name="R_index_proximal" file="R_index_proximal.STL"/>
    <mesh name="R_index_distal" file="R_index_distal.STL"/>
    <mesh name="R_middle_proximal" file="R_middle_proximal.STL"/>
    <mesh name="R_middle_distal" file="R_middle_distal.STL"/>
    <mesh name="R_ring_proximal" file="R_ring_proximal.STL"/>
    <mesh name="R_ring_distal" file="R_ring_distal.STL"/>
    <mesh name="R_pinky_proximal" file="R_pinky_proximal.STL"/>
    <mesh name="R_pinky_distal" file="R_pinky_distal.STL"/>
  </asset>

  <worldbody>
    <geom type="mesh" contype="0" conaffinity="0" group="1" density="0" rgba="0.82353 0.82353 1 1" mesh="base_link"/>
    <geom type="mesh" rgba="0.82353 0.82353 1 1" mesh="base_link"/>
    <body name="steer_motor_link1" pos="0.16897 0.28 0.15765">
      <inertial pos="7.7174e-06 -0.004623 -0.049428" quat="0.707095 -0.000176703 0.000138216 0.707118" mass="1.5" diaginertia="0.00032908 0.00022164 0.00015872"/>
      <joint name="steer_motor_joint1" pos="0 0 0" axis="0 0 1" range="-3.1416 3.1416" actuatorfrcrange="-50 50"/>
      <geom type="mesh" contype="0" conaffinity="0" group="1" density="0" rgba="0.82353 0.82353 1 1" mesh="steer_motor_link1"/>
      <geom type="mesh" rgba="0.82353 0.82353 1 1" mesh="steer_motor_link1"/>
      <body name="wheel_motor_link1" pos="0 0 -0.08765">
        <inertial pos="1.6481e-10 -1.6203e-10 -9.455e-10" quat="0.270598 0.653281 0.653281 0.270598" mass="1.5" diaginertia="0.0020893 0.00126281 0.00126279"/>
        <joint name="wheel_motor_joint1" pos="0 0 0" axis="0 1 0"/>
        <geom type="mesh" contype="0" conaffinity="0" group="1" density="0" rgba="0.82353 0.82353 1 1" mesh="wheel_motor_link1"/>
        <geom type="mesh" rgba="0.82353 0.82353 1 1" mesh="wheel_motor_link1"/>
      </body>
    </body>
    <body name="steer_motor_link2" pos="0.16897 -0.28 0.15765">
      <inertial pos="6.044e-06 0.00010023 -0.052223" quat="0.707092 -0.000520429 0.00047447 0.707122" mass="1.5" diaginertia="0.00037037 0.0002535 0.000163"/>
      <joint name="steer_motor_joint2" pos="0 0 0" axis="0 0 1" range="-3.1416 3.1416" actuatorfrcrange="-50 50"/>
      <geom type="mesh" contype="0" conaffinity="0" group="1" density="0" rgba="0.82353 0.82353 1 1" mesh="steer_motor_link2"/>
      <geom type="mesh" rgba="0.82353 0.82353 1 1" mesh="steer_motor_link2"/>
      <body name="wheel_motor_link2" pos="0 0 -0.08765">
        <inertial pos="1.6448e-10 -1.616e-10 -9.4549e-10" quat="0.270598 0.653281 0.653281 0.270598" mass="1.5" diaginertia="0.0020893 0.00126281 0.00126279"/>
        <joint name="wheel_motor_joint2" pos="0 0 0" axis="0 1 0"/>
        <geom type="mesh" contype="0" conaffinity="0" group="1" density="0" rgba="0.82353 0.82353 1 1" mesh="wheel_motor_link2"/>
        <geom type="mesh" rgba="0.82353 0.82353 1 1" mesh="wheel_motor_link2"/>
      </body>
    </body>
    <body name="steer_motor_link3" pos="-0.32703 0 0.15765">
      <inertial pos="-6.029e-06 -0.00010167 -0.052221" quat="0.707092 0.000512639 -0.000484659 0.707121" mass="1.5" diaginertia="0.00037036 0.0002535 0.000163"/>
      <joint name="steer_motor_joint3" pos="0 0 0" axis="0 0 1" range="-3.1416 3.1416" actuatorfrcrange="-50 50"/>
      <geom type="mesh" contype="0" conaffinity="0" group="1" density="0" rgba="0.82353 0.82353 1 1" mesh="steer_motor_link3"/>
      <geom type="mesh" rgba="0.82353 0.82353 1 1" mesh="steer_motor_link3"/>
      <body name="wheel_motor_link3" pos="0 0 -0.08765">
        <inertial pos="-2.443e-09 1.4779e-12 5.1754e-12" quat="0.270598 0.653281 0.653281 0.270598" mass="1.5" diaginertia="0.0020893 0.00126281 0.00126279"/>
        <joint name="wheel_motor_joint3" pos="0 0 0" axis="0 1 0"/>
        <geom type="mesh" contype="0" conaffinity="0" group="1" density="0" rgba="0.82353 0.82353 1 1" mesh="wheel_motor_link3"/>
        <geom type="mesh" rgba="0.82353 0.82353 1 1" mesh="wheel_motor_link3"/>
      </body>
    </body>
    <body name="torso_link1" pos="-0.079032 0 0.34265">
      <inertial pos="0.00065636 0.0032244 0.23142" quat="0.999998 0.000695924 0.000862045 0.00193552" mass="5.72" diaginertia="0.10931 0.10736 0.00812171"/>
      <joint name="torso_joint1" pos="0 0 0" axis="0 1 0" range="-1.1345 1.8326" actuatorfrcrange="-800 800"/>
      <geom type="mesh" contype="0" conaffinity="0" group="1" density="0" rgba="0.82353 0.82353 1 1" mesh="torso_link1"/>
      <geom type="mesh" rgba="0.82353 0.82353 1 1" mesh="torso_link1"/>
      <body name="torso_link2" pos="0 0 0.4">
        <inertial pos="0.0052517 0.014411 0.15711" quat="0.707019 -0.00357502 -0.00358594 0.707176" mass="3.5" diaginertia="0.027574 0.0260835 0.00184901"/>
        <joint name="torso_joint2" pos="0 0 0" axis="0 1 0" range="-2.7925 2.5307" actuatorfrcrange="-800 800"/>
        <geom type="mesh" contype="0" conaffinity="0" group="1" density="0" rgba="0.82353 0.82353 1 1" mesh="torso_link2"/>
        <geom type="mesh" rgba="0.82353 0.82353 1 1" mesh="torso_link2"/>
        <body name="torso_link3" pos="0 0.0001005 0.3">
          <inertial pos="-9.8337e-07 -0.0055146 0.020182" quat="0.493716 0.506467 0.494804 0.504882" mass="3.4" diaginertia="0.00230141 0.00170239 0.0016099"/>
          <joint name="torso_joint3" pos="0 0 0" axis="0 -1 0" range="-1.8326 1.5708" actuatorfrcrange="-800 800"/>
          <geom type="mesh" contype="0" conaffinity="0" group="1" density="0" rgba="0.82353 0.82353 1 1" mesh="torso_link3"/>
          <geom type="mesh" rgba="0.82353 0.82353 1 1" mesh="torso_link3"/>
          <body name="torso_link4" pos="0 -0.00010015 0.09962">
            <inertial pos="0.112243 0.0149664 0.195822" quat="0.224742 0.718429 0.438283 0.49118" mass="10.01" diaginertia="0.644244 0.633616 0.0615982"/>
            <joint name="torso_joint4" pos="0 0 0" axis="0 0 1" range="-3.0543 3.0543" actuatorfrcrange="-800 800"/>
            <geom type="mesh" contype="0" conaffinity="0" group="1" density="0" rgba="0.82353 0.82353 1 1" mesh="torso_link4"/>
            <geom type="mesh" rgba="0.82353 0.82353 1 1" mesh="torso_link4"/>
            <geom pos="0.065511 0.060003 0.47598" quat="0.405568 -0.579235 0.579237 -0.40557" type="mesh" contype="0" conaffinity="0" group="1" density="0" rgba="0.82353 0.82353 1 1" mesh="zed_link"/>
            <geom pos="0.065511 0.060003 0.47598" quat="0.405568 -0.579235 0.579237 -0.40557" type="mesh" rgba="0.82353 0.82353 1 1" mesh="zed_link"/>
            <geom pos="-0.00048618 0.097234 0.30302" quat="1 0 0 0" type="mesh" contype="0" conaffinity="0" group="1" density="0" rgba="0.82353 0.82353 1 1" mesh="left_arm_base_link"/>
            <geom pos="-0.00048618 0.097234 0.30302" quat="1 0 0 0" type="mesh" rgba="0.82353 0.82353 1 1" mesh="left_arm_base_link"/>
            <geom pos="-0.00048706 -0.097236 0.30302" quat="1 0 0 0" type="mesh" contype="0" conaffinity="0" group="1" density="0" rgba="0.82353 0.82353 1 1" mesh="right_arm_base_link"/>
            <geom pos="-0.00048706 -0.097236 0.30302" quat="1 0 0 0" type="mesh" rgba="0.82353 0.82353 1 1" mesh="right_arm_base_link"/>
            <body name="left_arm_link1" pos="-0.00048618 0.170734 0.30302">
              <inertial pos="0.00042258 0.074131 7.9156e-05" quat="0.705776 0.708428 0.000383566 -0.00300782" mass="1.135" diaginertia="0.000616038 0.000471359 0.000302583"/>
              <joint name="left_arm_joint1" pos="0 0 0" axis="0 1 0" range="-4.4506 1.309" actuatorfrcrange="-120 120"/>
              <geom type="mesh" contype="0" conaffinity="0" group="1" density="0" rgba="0.82353 0.82353 1 1" mesh="left_arm_link1"/>
              <geom type="mesh" rgba="0.82353 0.82353 1 1" mesh="left_arm_link1"/>
              <body name="left_arm_link2" pos="0.025012 0.081265 0">
                <inertial pos="-0.026826 -0.0040392 -0.031835" quat="0.967826 0.24999 -0.0279104 0.00629583" mass="0.92" diaginertia="0.000373948 0.000345466 0.000316696"/>
                <joint name="left_arm_joint2" pos="0 0 0" axis="1 0 0" range="-0.1745 3.1416" actuatorfrcrange="-120 120"/>
                <geom type="mesh" contype="0" conaffinity="0" group="1" density="0" rgba="0.82353 0.82353 1 1" mesh="left_arm_link2"/>
                <geom type="mesh" rgba="0.82353 0.82353 1 1" mesh="left_arm_link2"/>
                <body name="left_arm_link3" pos="-0.025012 0 -0.1155">
                  <inertial pos="0.0053849 -0.00086892 -0.1126" quat="0.987419 -0.0126124 0.157363 -0.00905809" mass="1.245" diaginertia="0.000765373 0.000738745 0.000331352"/>
                  <joint name="left_arm_joint3" pos="0 0 0" axis="0 0 1" range="-2.3562 2.3562" actuatorfrcrange="-80 80"/>
                  <geom type="mesh" contype="0" conaffinity="0" group="1" density="0" rgba="0.82353 0.82353 1 1" mesh="left_arm_link3"/>
                  <geom type="mesh" rgba="0.82353 0.82353 1 1" mesh="left_arm_link3"/>
                  <body name="left_arm_link4" pos="0 0.035065 -0.1945">
                    <inertial pos="-0.0011018 -0.036243 -0.042164" quat="0.70731 -0.0289938 -0.0395261 0.705202" mass="0.827" diaginertia="0.000197532 0.000139189 0.000101919"/>
                    <joint name="left_arm_joint4" pos="0 0 0" axis="0 1 0" range="-1.7453 0.3491" actuatorfrcrange="-80 80"/>
                    <geom type="mesh" contype="0" conaffinity="0" group="1" density="0" rgba="0.82353 0.82353 1 1" mesh="left_arm_link4"/>
                    <geom type="mesh" rgba="0.82353 0.82353 1 1" mesh="left_arm_link4"/>
                    <body name="left_arm_link5" pos="0 -0.035065 -0.095">
                      <inertial pos="3.7881e-07 -0.0028035 -0.062981" quat="0.997254 -0.074061 2.09046e-05 0.000268168" mass="0.939" diaginertia="0.00070496 0.000677819 0.000322221"/>
                      <joint name="left_arm_joint5" pos="0 0 0" axis="0 0 1" range="-2.3562 2.3562" actuatorfrcrange="-60 60"/>
                      <geom type="mesh" contype="0" conaffinity="0" group="1" density="0" rgba="0.82353 0.82353 1 1" mesh="left_arm_link5"/>
                      <geom type="mesh" rgba="0.82353 0.82353 1 1" mesh="left_arm_link5"/>
                      <body name="left_arm_link6" pos="0 -0.028 -0.16305">
                        <inertial pos="0.0017919 0.027487 0.00025471" quat="0.704102 0.696344 -0.110248 0.0847966" mass="0.527" diaginertia="8.56857e-05 8.24979e-05 8.11804e-05"/>
                        <joint name="left_arm_joint6" pos="0 0 0" axis="0 1 0" range="-1.0472 1.0472" actuatorfrcrange="-60 60"/>
                        <geom type="mesh" contype="0" conaffinity="0" group="1" density="0" rgba="0.82353 0.82353 1 1" mesh="left_arm_link6"/>
                        <geom type="mesh" rgba="0.82353 0.82353 1 1" mesh="left_arm_link6"/>
                        <body name="left_arm_link7" pos="0.0295 0.028 0">
                          <inertial pos="-0.0274901 -0.00891986 -0.0721294" quat="0.420659 -0.21629 -0.154447 0.867416" mass="0.280999" diaginertia="0.000818558 0.000669573 0.00022538"/>
                          <joint name="left_arm_joint7" pos="0 0 0" axis="1 0 0" range="-1.5708 1.5708" actuatorfrcrange="-60 60"/>
                          <geom type="mesh" contype="0" conaffinity="0" group="1" density="0" rgba="0.82353 0.82353 1 1" mesh="left_arm_link7"/>
                          <geom type="mesh" rgba="0.82353 0.82353 1 1" mesh="left_arm_link7"/>
                          <geom pos="-0.0295 0 -0.084" quat="1 0 0 0" type="mesh" contype="0" conaffinity="0" group="1" density="0" rgba="1 1 1 1" mesh="L_hand_base_link"/>
                          <geom pos="-0.0295 0 -0.084" quat="1 0 0 0" type="mesh" rgba="1 1 1 1" mesh="L_hand_base_link"/>
                          <geom pos="-0.0290145 -0.02096 -0.166692" quat="1 0 0 0" type="mesh" contype="0" conaffinity="0" group="1" density="0" rgba="1 1 1 1" mesh="L_hand_palm_link"/>
                          <geom pos="-0.0290145 -0.02096 -0.166692" quat="1 0 0 0" type="mesh" rgba="1 1 1 1" mesh="L_hand_palm_link"/>
                          <site name="left_hand_tcp" pos="-0.0295 0 -0.145" quat="0.70710678 0.70710678 0 0" size="0.006" rgba="1 0.2 0.2 1"/>
                          <body name="L_thumb_proximal_base" pos="-0.00905 -0.01696 -0.1446">
                            <inertial pos="0.00357733 -0.00251129 -0.00066932" quat="0.60383 0.732097 0.236844 0.208154" mass="0.00171905" diaginertia="7.57932e-08 6.06626e-08 4.40659e-08"/>
                            <joint name="L_thumb_MCP_joint1" pos="0 0 0" axis="0 0 -1" range="0 1.1" actuatorfrcrange="-50 50"/>
                            <geom type="mesh" contype="0" conaffinity="0" group="1" density="0" rgba="1 1 1 1" mesh="L_thumb_proximal_base"/>
                            <geom type="mesh" rgba="1 1 1 1" mesh="L_thumb_proximal_base"/>
                            <body name="L_thumb_proximal" pos="0.0086232 -0.0076086 0.00075003" quat="0.911486 0 0 0.411332">
                              <inertial pos="-0.000292493 -0.0213781 -0.0146404" quat="0.3993 0.91682 -0.000889294 0.000720044" mass="0.00716306" diaginertia="2.83788e-06 2.46057e-06 9.03115e-07"/>
                              <joint name="L_thumb_MCP_joint2" pos="0 0 0" axis="1 0 0" range="0 0.5" actuatorfrcrange="-50 50"/>
                              <geom type="mesh" contype="0" conaffinity="0" group="1" density="0" rgba="1 1 1 1" mesh="L_thumb_proximal"/>
                              <geom type="mesh" rgba="1 1 1 1" mesh="L_thumb_proximal"/>
                              <body name="L_thumb_intermediate" pos="0.0001 -0.043972 -0.030075">
                                <inertial pos="-9.42606e-05 -0.00765673 -0.0066496" quat="0.960257 -0.279118 2.15605e-05 -6.26699e-06" mass="0.00409345" diaginertia="4.60453e-07 4.49311e-07 2.53326e-07"/>
                                <joint name="L_thumb_PIP_joint" pos="0 0 0" axis="1 0 0" range="0 1" actuatorfrcrange="-50 50"/>
                                <geom type="mesh" contype="0" conaffinity="0" group="1" density="0" rgba="1 1 1 1" mesh="L_thumb_intermediate"/>
                                <geom type="mesh" rgba="1 1 1 1" mesh="L_thumb_intermediate"/>
                                <body name="L_thumb_distal" pos="-0.0001 -0.017066 -0.019311">
                                  <inertial pos="-3.40703e-06 -0.00857257 -0.00630128" quat="0.947577 -0.319519 -0.00135036 -0.00193728" mass="0.00330864" diaginertia="1.96166e-07 1.91285e-07 8.09839e-08"/>
                                  <joint name="L_thumb_DIP_joint" pos="0 0 0" axis="1 0 0" range="0 1.2" actuatorfrcrange="-50 50"/>
                                  <geom type="mesh" contype="0" conaffinity="0" group="1" density="0" rgba="1 1 1 1" mesh="L_thumb_distal"/>
                                  <geom type="mesh" rgba="1 1 1 1" mesh="L_thumb_distal"/>
                                </body>
                              </body>
                            </body>
                          </body>
                          <body name="L_index_proximal" pos="-0.003228 0.00028494 -0.22074" quat="0.999848 0 -0.0174546 0">
                            <inertial pos="-2.89287e-09 -0.00171709 -0.0129689" quat="0.702114 0.0838773 -0.0838773 0.702114" mass="0.000436731" diaginertia="4.04456e-08 3.87917e-08 2.79197e-09"/>
                            <joint name="L_index_MCP_joint" pos="0 0 0" axis="-1 0 0" range="0 1.7" actuatorfrcrange="-50 50"/>
                            <geom type="mesh" contype="0" conaffinity="0" group="1" density="0" rgba="1 1 1 1" mesh="L_index_proximal"/>
                            <geom type="mesh" rgba="1 1 1 1" mesh="L_index_proximal"/>
                            <body name="L_index_distal" pos="0 -0.0027965 -0.03201">
                              <inertial pos="-1.63033e-07 0.00188902 -0.0194852" quat="0.997155 -0.0753772 1.26278e-05 0.000167051" mass="0.00463375" diaginertia="7.84452e-07 7.75838e-07 8.34276e-08"/>
                              <joint name="L_index_DIP_joint" pos="0 0 0" axis="-1 0 0" range="0 1.6" actuatorfrcrange="-50 50"/>
                              <geom type="mesh" contype="0" conaffinity="0" group="1" density="0" rgba="1 1 1 1" mesh="L_index_distal"/>
                              <geom type="mesh" rgba="1 1 1 1" mesh="L_index_distal"/>
                            </body>
                          </body>
                          <body name="L_middle_proximal" pos="-0.0225493 0.00028503 -0.2211">
                            <inertial pos="-2.73484e-09 -0.00171709 -0.0129689" quat="0.702114 0.0838773 -0.0838773 0.702114" mass="0.000436731" diaginertia="4.04456e-08 3.87917e-08 2.79197e-09"/>
                            <joint name="L_middle_MCP_joint" pos="0 0 0" axis="-1 0 0" range="0 1.68" actuatorfrcrange="-50 50"/>
                            <geom type="mesh" contype="0" conaffinity="0" group="1" density="0" rgba="1 1 1 1" mesh="L_middle_proximal"/>
                            <geom type="mesh" rgba="1 1 1 1" mesh="L_middle_proximal"/>
                            <body name="L_middle_distal" pos="0 -0.0027965 -0.03201">
                              <inertial pos="-1.18888e-07 0.00150375 -0.0209788" quat="0.996982 -0.0776326 1.11441e-05 0.000154095" mass="0.00500331" diaginertia="9.6838e-07 9.58492e-07 9.04243e-08"/>
                              <joint name="L_middle_DIP_joint" pos="0 0 0" axis="-1 0 0" range="0 1.6" actuatorfrcrange="-50 50"/>
                              <geom type="mesh" contype="0" conaffinity="0" group="1" density="0" rgba="1 1 1 1" mesh="L_middle_distal"/>
                              <geom type="mesh" rgba="1 1 1 1" mesh="L_middle_distal"/>
                            </body>
                          </body>
                          <body name="L_ring_proximal" pos="-0.041778 0.00028511 -0.2206" quat="0.999657 0 0.0261745 0">
                            <inertial pos="-2.51457e-09 -0.00171709 -0.0129689" quat="0.702114 0.0838774 -0.0838774 0.702114" mass="0.000436731" diaginertia="4.04456e-08 3.87917e-08 2.79197e-09"/>
                            <joint name="L_ring_MCP_joint" pos="0 0 0" axis="-1 0 0" range="0 1.7" actuatorfrcrange="-50 50"/>
                            <geom type="mesh" contype="0" conaffinity="0" group="1" density="0" rgba="1 1 1 1" mesh="L_ring_proximal"/>
                            <geom type="mesh" rgba="1 1 1 1" mesh="L_ring_proximal"/>
                            <body name="L_ring_distal" pos="0 -0.0027965 -0.03201">
                              <inertial pos="-1.60648e-07 0.00188902 -0.0194852" quat="0.997155 -0.0753773 1.19109e-05 0.000157568" mass="0.00463375" diaginertia="7.84452e-07 7.75837e-07 8.34275e-08"/>
                              <joint name="L_ring_DIP_joint" pos="0 0 0" axis="-1 0 0" range="0 1.6" actuatorfrcrange="-50 50"/>
                              <geom type="mesh" contype="0" conaffinity="0" group="1" density="0" rgba="1 1 1 1" mesh="L_ring_distal"/>
                              <geom type="mesh" rgba="1 1 1 1" mesh="L_ring_distal"/>
                            </body>
                          </body>
                          <body name="L_pinky_proximal" pos="-0.060954 0.0002852 -0.21909" quat="0.99863 0 0.0523361 0">
                            <inertial pos="0 0 0" quat="0.999969 0.00787047 0 0" mass="0.004404" diaginertia="6.5597e-07 6.25621e-07 2.18879e-07"/>
                            <joint name="L_pinky_MCP_joint" pos="0 0 0" axis="-1 0 0" range="0 1.7" actuatorfrcrange="-50 50"/>
                            <geom type="mesh" contype="0" conaffinity="0" group="1" density="0" rgba="1 1 1 1" mesh="L_pinky_proximal"/>
                            <geom type="mesh" rgba="1 1 1 1" mesh="L_pinky_proximal"/>
                            <body name="L_pinky_distal" pos="0 -0.0027965 -0.03201">
                              <inertial pos="-1.13071e-07 0.00226829 -0.0159776" quat="0.997106 -0.0760169 2.09199e-05 0.000254463" mass="0.00370409" diaginertia="4.43372e-07 4.38482e-07 6.4408e-08"/>
                              <joint name="L_pinky_DIP_joint" pos="0 0 0" axis="-1 0 0" range="0 1.6" actuatorfrcrange="-50 50"/>
                              <geom type="mesh" contype="0" conaffinity="0" group="1" density="0" rgba="1 1 1 1" mesh="L_pinky_distal"/>
                              <geom type="mesh" rgba="1 1 1 1" mesh="L_pinky_distal"/>
                            </body>
                          </body>
                        </body>
                      </body>
                    </body>
                  </body>
                </body>
              </body>
            </body>
            <body name="right_arm_link1" pos="-0.00048706 -0.170736 0.30302">
              <inertial pos="-0.00042261 -0.074132 7.8365e-05" quat="0.708417 0.705787 -0.00300924 0.000384982" mass="1.135" diaginertia="0.000616038 0.000471349 0.000302583"/>
              <joint name="right_arm_joint1" pos="0 0 0" axis="0 1 0" range="-4.4506 1.309" actuatorfrcrange="-120 120"/>
              <geom type="mesh" contype="0" conaffinity="0" group="1" density="0" rgba="0.82353 0.82353 1 1" mesh="right_arm_link1"/>
              <geom type="mesh" rgba="0.82353 0.82353 1 1" mesh="right_arm_link1"/>
              <body name="right_arm_link2" pos="0.023988 -0.081265 0">
                <inertial pos="-0.022361 0.0049527 -0.032732" quat="0.973837 -0.224135 0.0325444 0.0186079" mass="0.92" diaginertia="0.000382057 0.000345953 0.00032461"/>
                <joint name="right_arm_joint2" pos="0 0 0" axis="1 0 0" range="-3.1416 0.1745" actuatorfrcrange="-120 120"/>
                <geom type="mesh" contype="0" conaffinity="0" group="1" density="0" rgba="0.82353 0.82353 1 1" mesh="right_arm_link2"/>
                <geom type="mesh" rgba="0.82353 0.82353 1 1" mesh="right_arm_link2"/>
                <body name="right_arm_link3" pos="-0.023988 0 -0.1155">
                  <inertial pos="0.0053839 -0.00087109 -0.11261" quat="0.987422 -0.0126678 0.15733 -0.00924199" mass="1.245" diaginertia="0.000765324 0.000738726 0.00033133"/>
                  <joint name="right_arm_joint3" pos="0 0 0" axis="0 0 1" range="-2.3562 2.3562" actuatorfrcrange="-80 80"/>
                  <geom type="mesh" contype="0" conaffinity="0" group="1" density="0" rgba="0.82353 0.82353 1 1" mesh="right_arm_link3"/>
                  <geom type="mesh" rgba="0.82353 0.82353 1 1" mesh="right_arm_link3"/>
                  <body name="right_arm_link4" pos="0 0.035058 -0.1945">
                    <inertial pos="-0.00058877 -0.035687 -0.057422" quat="0.707245 -0.0306329 -0.0413532 0.705093" mass="0.827" diaginertia="0.000220262 0.000161937 0.000126441"/>
                    <joint name="right_arm_joint4" pos="0 0 0" axis="0 1 0" range="-1.7453 0.3491" actuatorfrcrange="-80 80"/>
                    <geom type="mesh" contype="0" conaffinity="0" group="1" density="0" rgba="0.82353 0.82353 1 1" mesh="right_arm_link4"/>
                    <geom type="mesh" rgba="0.82353 0.82353 1 1" mesh="right_arm_link4"/>
                    <body name="right_arm_link5" pos="0 -0.035058 -0.095">
                      <inertial pos="-2.2815e-07 0.0031762 -0.07334" quat="0.997325 0.0730935 -2.18067e-05 0.000267049" mass="0.63" diaginertia="0.00069134 0.000664096 0.000303914"/>
                      <joint name="right_arm_joint5" pos="0 0 0" axis="0 0 1" range="-2.3562 2.3562" actuatorfrcrange="-60 60"/>
                      <geom type="mesh" contype="0" conaffinity="0" group="1" density="0" rgba="0.82353 0.82353 1 1" mesh="right_arm_link5"/>
                      <geom type="mesh" rgba="0.82353 0.82353 1 1" mesh="right_arm_link5"/>
                      <body name="right_arm_link6" pos="0 0.028001 -0.16305">
                        <inertial pos="0.0017914 -0.027486 0.00025485" quat="0.696434 0.70404 -0.0847037 0.110151" mass="0.527" diaginertia="8.56852e-05 8.24984e-05 8.11794e-05"/>
                        <joint name="right_arm_joint6" pos="0 0 0" axis="0 1 0" range="-1.0472 1.0472" actuatorfrcrange="-60 60"/>
                        <geom type="mesh" contype="0" conaffinity="0" group="1" density="0" rgba="0.82353 0.82353 1 1" mesh="right_arm_link6"/>
                        <geom type="mesh" rgba="0.82353 0.82353 1 1" mesh="right_arm_link6"/>
                        <body name="right_arm_link7" pos="0.0295 -0.028001 0">
                          <inertial pos="-0.0344094 -0.0124367 -0.0814087" quat="0.658032 -0.0873106 0.156434 0.731368" mass="0.298851" diaginertia="0.000956624 0.000818731 0.000230347"/>
                          <joint name="right_arm_joint7" pos="0 0 0" axis="1 0 0" range="-1.5708 1.5708" actuatorfrcrange="-60 60"/>
                          <geom type="mesh" contype="0" conaffinity="0" group="1" density="0" rgba="0.82353 0.82353 1 1" mesh="right_arm_link7"/>
                          <geom type="mesh" rgba="0.82353 0.82353 1 1" mesh="right_arm_link7"/>
                          <geom pos="-0.0295 0 -0.084" quat="1 0 0 0" type="mesh" contype="0" conaffinity="0" group="1" density="0" rgba="0.89804 0.91373 0.92549 1" mesh="R_hand_base_link"/>
                          <geom pos="-0.0295 0 -0.084" quat="1 0 0 0" type="mesh" rgba="0.89804 0.91373 0.92549 1" mesh="R_hand_base_link"/>
                          <geom pos="-0.0290132 0.020961 -0.166692" quat="1 0 0 0" type="mesh" contype="0" conaffinity="0" group="1" density="0" rgba="0.79216 0.81961 0.93333 1" mesh="R_hand_palm_link"/>
                          <geom pos="-0.0290132 0.020961 -0.166692" quat="1 0 0 0" type="mesh" rgba="0.79216 0.81961 0.93333 1" mesh="R_hand_palm_link"/>
                          <site name="right_hand_tcp" pos="-0.0295 0 -0.145" quat="0.70710678 0.70710678 0 0" size="0.006" rgba="1 0.2 0.2 1"/>
                          <body name="R_thumb_proximal_base" pos="-0.00905 0.016961 -0.1446">
                            <inertial pos="0.0035776 0.0025114 -0.00066949" quat="0.732083 0.603839 -0.208171 -0.236852" mass="0.001719" diaginertia="7.57985e-08 6.06699e-08 4.40616e-08"/>
                            <joint name="R_thumb_MCP_joint1" pos="0 0 0" axis="0 0 1" range="0 1.1" actuatorfrcrange="-50 50"/>
                            <geom type="mesh" contype="0" conaffinity="0" group="1" density="0" rgba="0.82745 0.83922 0.82745 1" mesh="R_thumb_proximal_base"/>
                            <geom type="mesh" rgba="0.82745 0.83922 0.82745 1" mesh="R_thumb_proximal_base"/>
                            <body name="R_thumb_proximal" pos="0.0086233 0.0076085 0.00075" quat="0.911484 0 0 -0.411337">
                              <inertial pos="-2.9202e-05 0.021737 -0.014506" quat="0.919758 0.392485 -0.000721155 0.000834252" mass="0.0067546" diaginertia="2.7612e-06 2.39151e-06 8.93392e-07"/>
                              <joint name="R_thumb_MCP_joint2" pos="0 0 0" axis="-1 0 0" range="0 0.5" actuatorfrcrange="-50 50"/>
                              <geom type="mesh" contype="0" conaffinity="0" group="1" density="0" rgba="0.79216 0.81961 0.92941 1" mesh="R_thumb_proximal"/>
                              <geom type="mesh" rgba="0.79216 0.81961 0.92941 1" mesh="R_thumb_proximal"/>
                              <body name="R_thumb_intermediate" pos="0.0001 0.042177 -0.03684">
                                <inertial pos="-9.1769e-05 0.0094763 0.000146" quat="0.959866 0.280383 -0.0019431 0.00621858" mass="0.0040782" diaginertia="4.58712e-07 4.49132e-07 2.51776e-07"/>
                                <joint name="R_thumb_PIP_joint" pos="0 0 0" axis="-1 0 0" range="0 1" actuatorfrcrange="-50 50"/>
                                <geom type="mesh" contype="0" conaffinity="0" group="1" density="0" rgba="1 1 1 1" mesh="R_thumb_intermediate"/>
                                <geom type="mesh" rgba="1 1 1 1" mesh="R_thumb_intermediate"/>
                                <body name="R_thumb_distal" pos="-0.0001 0.018862 -0.012545">
                                  <inertial pos="-3.3928e-06 0.0085726 -0.0063011" quat="0.947576 0.31952 -0.00135139 0.00193796" mass="0.0033086" diaginertia="1.9617e-07 1.91286e-07 8.09833e-08"/>
                                  <joint name="R_thumb_DIP_joint" pos="0 0 0" axis="-1 0 0" range="0 1.2" actuatorfrcrange="-50 50"/>
                                  <geom type="mesh" contype="0" conaffinity="0" group="1" density="0" rgba="1 1 1 1" mesh="R_thumb_distal"/>
                                  <geom type="mesh" rgba="1 1 1 1" mesh="R_thumb_distal"/>
                                </body>
                              </body>
                            </body>
                          </body>
                          <body name="R_index_proximal" pos="-0.003229 -0.0002841 -0.22074" quat="0.999848 0 -0.0174516 0">
                            <inertial pos="5.2077e-08 -0.00063565 -0.012457" quat="0.999969 0.00787034 1.46424e-07 -1.86039e-05" mass="0.004404" diaginertia="6.5596e-07 6.25621e-07 2.18879e-07"/>
                            <joint name="R_index_MCP_joint" pos="0 0 0" axis="1 0 0" range="0 1.7" actuatorfrcrange="-50 50"/>
                            <geom type="mesh" contype="0" conaffinity="0" group="1" density="0" rgba="0.79216 0.81961 0.92941 1" mesh="R_index_proximal"/>
                            <geom type="mesh" rgba="0.79216 0.81961 0.92941 1" mesh="R_index_proximal"/>
                            <body name="R_index_distal" pos="0 0.0027966 -0.03201">
                              <inertial pos="-6.195e-08 -0.0018889 -0.019485" quat="0.997155 0.0753755 1.21453e-05 -0.000160672" mass="0.0046337" diaginertia="7.8445e-07 7.75826e-07 8.34281e-08"/>
                              <joint name="R_index_DIP_joint" pos="0 0 0" axis="1 0 0" range="0 1.6" actuatorfrcrange="-50 50"/>
                              <geom type="mesh" contype="0" conaffinity="0" group="1" density="0" rgba="1 1 1 1" mesh="R_index_distal"/>
                              <geom type="mesh" rgba="1 1 1 1" mesh="R_index_distal"/>
                            </body>
                          </body>
                          <body name="R_middle_proximal" pos="-0.02255 -0.00028401 -0.2211">
                            <inertial pos="3.2881e-08 -0.00063558 -0.012457" quat="0.999969 0.00786973 0 0" mass="0.004404" diaginertia="6.5597e-07 6.25621e-07 2.18879e-07"/>
                            <joint name="R_middle_MCP_joint" pos="0 0 0" axis="1 0 0" range="0 1.68" actuatorfrcrange="-50 50"/>
                            <geom type="mesh" contype="0" conaffinity="0" group="1" density="0" rgba="0.79216 0.81961 0.92941 1" mesh="R_middle_proximal"/>
                            <geom type="mesh" rgba="0.79216 0.81961 0.92941 1" mesh="R_middle_proximal"/>
                            <body name="R_middle_distal" pos="0 0.0027966 -0.03201">
                              <inertial pos="-1.1832e-07 -0.0015037 -0.020979" quat="0.996982 0.0776337 8.06866e-06 -0.000103619" mass="0.0050034" diaginertia="9.6839e-07 9.58512e-07 9.04182e-08"/>
                              <joint name="R_middle_DIP_joint" pos="0 0 0" axis="1 0 0" range="0 1.6" actuatorfrcrange="-50 50"/>
                              <geom type="mesh" contype="0" conaffinity="0" group="1" density="0" rgba="1 1 1 1" mesh="R_middle_distal"/>
                              <geom type="mesh" rgba="1 1 1 1" mesh="R_middle_distal"/>
                            </body>
                          </body>
                          <body name="R_ring_proximal" pos="-0.041779 -0.00028393 -0.2206" quat="0.999657 0 0.026178 0">
                            <inertial pos="1.2273e-08 -0.00063564 -0.012457" quat="0.999969 0.00787047 0 0" mass="0.004404" diaginertia="6.5597e-07 6.25621e-07 2.18879e-07"/>
                            <joint name="R_ring_MCP_joint" pos="0 0 0" axis="1 0 0" range="0 1.7" actuatorfrcrange="-50 50"/>
                            <geom type="mesh" contype="0" conaffinity="0" group="1" density="0" rgba="0.79216 0.81961 0.92941 1" mesh="R_ring_proximal"/>
                            <geom type="mesh" rgba="0.79216 0.81961 0.92941 1" mesh="R_ring_proximal"/>
                            <body name="R_ring_distal" pos="0 0.0027966 -0.03201">
                              <inertial pos="-6.1891e-08 -0.0018889 -0.019485" quat="0.997155 0.0753754 1.25114e-05 -0.000154588" mass="0.0046337" diaginertia="7.8444e-07 7.75826e-07 8.34271e-08"/>
                              <joint name="R_ring_DIP_joint" pos="0 0 0" axis="1 0 0" range="0 1.6" actuatorfrcrange="-50 50"/>
                              <geom type="mesh" contype="0" conaffinity="0" group="1" density="0" rgba="1 1 1 1" mesh="R_ring_distal"/>
                              <geom type="mesh" rgba="1 1 1 1" mesh="R_ring_distal"/>
                            </body>
                          </body>
                          <body name="R_pinky_proximal" pos="-0.060955 -0.00028384 -0.21909" quat="0.99863 0 0.0523361 0">
                            <inertial pos="1.0964e-08 -0.00063564 -0.012457" quat="0.999969 0.00787047 0 0" mass="0.004404" diaginertia="6.5597e-07 6.25621e-07 2.18879e-07"/>
                            <joint name="R_pinky_MCP_joint" pos="0 0 0" axis="1 0 0" range="0 1.7" actuatorfrcrange="-50 50"/>
                            <geom type="mesh" contype="0" conaffinity="0" group="1" density="0" rgba="0.79216 0.81961 0.92941 1" mesh="R_pinky_proximal"/>
                            <geom type="mesh" rgba="0.79216 0.81961 0.92941 1" mesh="R_pinky_proximal"/>
                            <body name="R_pinky_distal" pos="0 0.0027967 -0.03201">
                              <inertial pos="-3.8189e-07 -0.0022677 -0.015978" quat="0.997107 0.0760141 4.28461e-05 -0.000608481" mass="0.0037038" diaginertia="4.4337e-07 4.38486e-07 6.43988e-08"/>
                              <joint name="R_pinky_DIP_joint" pos="0 0 0" axis="1 0 0" range="0 1.6" actuatorfrcrange="-50 50"/>
                              <geom type="mesh" contype="0" conaffinity="0" group="1" density="0" rgba="1 1 1 1" mesh="R_pinky_distal"/>
                              <geom type="mesh" rgba="1 1 1 1" mesh="R_pinky_distal"/>
                            </body>
                          </body>
                        </body>
                      </body>
                    </body>
                  </body>
                </body>
              </body>
            </body>
          </body>
        </body>
      </body>
    </body>
  </worldbody>
  <equality>
    <joint name="L_thumb_PIP_mimic" joint1="L_thumb_PIP_joint" joint2="L_thumb_MCP_joint2" polycoef="0 1.6 0 0 0"/>
    <joint name="L_thumb_DIP_mimic" joint1="L_thumb_DIP_joint" joint2="L_thumb_MCP_joint2" polycoef="0 2.4 0 0 0"/>
    <joint name="L_index_DIP_mimic" joint1="L_index_DIP_joint" joint2="L_index_MCP_joint" polycoef="0 1 0 0 0"/>
    <joint name="L_middle_DIP_mimic" joint1="L_middle_DIP_joint" joint2="L_middle_MCP_joint" polycoef="0 1 0 0 0"/>
    <joint name="L_ring_DIP_mimic" joint1="L_ring_DIP_joint" joint2="L_ring_MCP_joint" polycoef="0 1 0 0 0"/>
    <joint name="L_pinky_DIP_mimic" joint1="L_pinky_DIP_joint" joint2="L_pinky_MCP_joint" polycoef="0 1 0 0 0"/>
    <joint name="R_thumb_PIP_mimic" joint1="R_thumb_PIP_joint" joint2="R_thumb_MCP_joint2" polycoef="0 1.6 0 0 0"/>
    <joint name="R_thumb_DIP_mimic" joint1="R_thumb_DIP_joint" joint2="R_thumb_MCP_joint2" polycoef="0 2.4 0 0 0"/>
    <joint name="R_index_DIP_mimic" joint1="R_index_DIP_joint" joint2="R_index_MCP_joint" polycoef="0 1 0 0 0"/>
    <joint name="R_middle_DIP_mimic" joint1="R_middle_DIP_joint" joint2="R_middle_MCP_joint" polycoef="0 1 0 0 0"/>
    <joint name="R_ring_DIP_mimic" joint1="R_ring_DIP_joint" joint2="R_ring_MCP_joint" polycoef="0 1 0 0 0"/>
    <joint name="R_pinky_DIP_mimic" joint1="R_pinky_DIP_joint" joint2="R_pinky_MCP_joint" polycoef="0 1 0 0 0"/>
  </equality>
  <actuator>
    <!-- Base drive -->
    <general name="steer_motor_joint1_pos" joint="steer_motor_joint1" gaintype="fixed" biastype="affine" gainprm="1500" biasprm="0 -1500 -250" ctrllimited="true" ctrlrange="-3.1416 3.1416" forcelimited="true" forcerange="-80 80"/>
    <general name="wheel_motor_joint1_pos" joint="wheel_motor_joint1" gaintype="fixed" biastype="affine" gainprm="1500" biasprm="0 -1500 -250" ctrllimited="false" forcelimited="true" forcerange="-80 80"/>
    <general name="steer_motor_joint2_pos" joint="steer_motor_joint2" gaintype="fixed" biastype="affine" gainprm="1500" biasprm="0 -1500 -250" ctrllimited="true" ctrlrange="-3.1416 3.1416" forcelimited="true" forcerange="-80 80"/>
    <general name="wheel_motor_joint2_pos" joint="wheel_motor_joint2" gaintype="fixed" biastype="affine" gainprm="1500" biasprm="0 -1500 -250" ctrllimited="false" forcelimited="true" forcerange="-80 80"/>
    <general name="steer_motor_joint3_pos" joint="steer_motor_joint3" gaintype="fixed" biastype="affine" gainprm="1500" biasprm="0 -1500 -250" ctrllimited="true" ctrlrange="-3.1416 3.1416" forcelimited="true" forcerange="-80 80"/>
    <general name="wheel_motor_joint3_pos" joint="wheel_motor_joint3" gaintype="fixed" biastype="affine" gainprm="1500" biasprm="0 -1500 -250" ctrllimited="false" forcelimited="true" forcerange="-80 80"/>

    <!-- Torso -->
    <general name="torso_joint1_pos" joint="torso_joint1" gaintype="fixed" biastype="affine" gainprm="6000" biasprm="0 -6000 -800" ctrllimited="true" ctrlrange="-1.1345 1.8326" forcelimited="true" forcerange="-800 800"/>
    <general name="torso_joint2_pos" joint="torso_joint2" gaintype="fixed" biastype="affine" gainprm="6000" biasprm="0 -6000 -800" ctrllimited="true" ctrlrange="-2.7925 2.5307" forcelimited="true" forcerange="-800 800"/>
    <general name="torso_joint3_pos" joint="torso_joint3" gaintype="fixed" biastype="affine" gainprm="6000" biasprm="0 -6000 -800" ctrllimited="true" ctrlrange="-1.8326 1.5708" forcelimited="true" forcerange="-800 800"/>
    <general name="torso_joint4_pos" joint="torso_joint4" gaintype="fixed" biastype="affine" gainprm="6000" biasprm="0 -6000 -800" ctrllimited="true" ctrlrange="-3.0543 3.0543" forcelimited="true" forcerange="-800 800"/>

    <!-- Left arm -->
    <general name="left_arm_joint1_pos" joint="left_arm_joint1" gaintype="fixed" biastype="affine" gainprm="7000" biasprm="0 -7000 -900" ctrllimited="true" ctrlrange="-4.4506 1.3090" forcelimited="true" forcerange="-120 120"/>
    <general name="left_arm_joint2_pos" joint="left_arm_joint2" gaintype="fixed" biastype="affine" gainprm="7000" biasprm="0 -7000 -900" ctrllimited="true" ctrlrange="-0.1745 3.1416" forcelimited="true" forcerange="-120 120"/>
    <general name="left_arm_joint3_pos" joint="left_arm_joint3" gaintype="fixed" biastype="affine" gainprm="5000" biasprm="0 -5000 -700" ctrllimited="true" ctrlrange="-2.3562 2.3562" forcelimited="true" forcerange="-80 80"/>
    <general name="left_arm_joint4_pos" joint="left_arm_joint4" gaintype="fixed" biastype="affine" gainprm="5000" biasprm="0 -5000 -700" ctrllimited="true" ctrlrange="-1.7453 0.3491" forcelimited="true" forcerange="-80 80"/>
    <general name="left_arm_joint5_pos" joint="left_arm_joint5" gaintype="fixed" biastype="affine" gainprm="4000" biasprm="0 -4000 -500" ctrllimited="true" ctrlrange="-2.3562 2.3562" forcelimited="true" forcerange="-60 60"/>
    <general name="left_arm_joint6_pos" joint="left_arm_joint6" gaintype="fixed" biastype="affine" gainprm="4000" biasprm="0 -4000 -500" ctrllimited="true" ctrlrange="-1.0472 1.0472" forcelimited="true" forcerange="-60 60"/>
    <general name="left_arm_joint7_pos" joint="left_arm_joint7" gaintype="fixed" biastype="affine" gainprm="4000" biasprm="0 -4000 -500" ctrllimited="true" ctrlrange="-1.5708 1.5708" forcelimited="true" forcerange="-60 60"/>

    <!-- Left hand -->
    <general name="L_thumb_MCP_joint1_pos" joint="L_thumb_MCP_joint1" gaintype="fixed" biastype="affine" gainprm="800" biasprm="0 -800 -80" ctrllimited="true" ctrlrange="0 1.1" forcelimited="true" forcerange="-20 20"/>
    <general name="L_thumb_MCP_joint2_pos" joint="L_thumb_MCP_joint2" gaintype="fixed" biastype="affine" gainprm="800" biasprm="0 -800 -80" ctrllimited="true" ctrlrange="0 0.5" forcelimited="true" forcerange="-20 20"/>
    <general name="L_index_MCP_joint_pos" joint="L_index_MCP_joint" gaintype="fixed" biastype="affine" gainprm="800" biasprm="0 -800 -80" ctrllimited="true" ctrlrange="0 1.7" forcelimited="true" forcerange="-20 20"/>
    <general name="L_middle_MCP_joint_pos" joint="L_middle_MCP_joint" gaintype="fixed" biastype="affine" gainprm="800" biasprm="0 -800 -80" ctrllimited="true" ctrlrange="0 1.68" forcelimited="true" forcerange="-20 20"/>
    <general name="L_ring_MCP_joint_pos" joint="L_ring_MCP_joint" gaintype="fixed" biastype="affine" gainprm="800" biasprm="0 -800 -80" ctrllimited="true" ctrlrange="0 1.7" forcelimited="true" forcerange="-20 20"/>
    <general name="L_pinky_MCP_joint_pos" joint="L_pinky_MCP_joint" gaintype="fixed" biastype="affine" gainprm="800" biasprm="0 -800 -80" ctrllimited="true" ctrlrange="0 1.7" forcelimited="true" forcerange="-20 20"/>

    <!-- Right arm -->
    <general name="right_arm_joint1_pos" joint="right_arm_joint1" gaintype="fixed" biastype="affine" gainprm="7000" biasprm="0 -7000 -900" ctrllimited="true" ctrlrange="-4.4506 1.3090" forcelimited="true" forcerange="-120 120"/>
    <general name="right_arm_joint2_pos" joint="right_arm_joint2" gaintype="fixed" biastype="affine" gainprm="7000" biasprm="0 -7000 -900" ctrllimited="true" ctrlrange="-3.1416 0.1745" forcelimited="true" forcerange="-120 120"/>
    <general name="right_arm_joint3_pos" joint="right_arm_joint3" gaintype="fixed" biastype="affine" gainprm="5000" biasprm="0 -5000 -700" ctrllimited="true" ctrlrange="-2.3562 2.3562" forcelimited="true" forcerange="-80 80"/>
    <general name="right_arm_joint4_pos" joint="right_arm_joint4" gaintype="fixed" biastype="affine" gainprm="5000" biasprm="0 -5000 -700" ctrllimited="true" ctrlrange="-1.7453 0.3491" forcelimited="true" forcerange="-80 80"/>
    <general name="right_arm_joint5_pos" joint="right_arm_joint5" gaintype="fixed" biastype="affine" gainprm="4000" biasprm="0 -4000 -500" ctrllimited="true" ctrlrange="-2.3562 2.3562" forcelimited="true" forcerange="-60 60"/>
    <general name="right_arm_joint6_pos" joint="right_arm_joint6" gaintype="fixed" biastype="affine" gainprm="4000" biasprm="0 -4000 -500" ctrllimited="true" ctrlrange="-1.0472 1.0472" forcelimited="true" forcerange="-60 60"/>
    <general name="right_arm_joint7_pos" joint="right_arm_joint7" gaintype="fixed" biastype="affine" gainprm="4000" biasprm="0 -4000 -500" ctrllimited="true" ctrlrange="-1.5708 1.5708" forcelimited="true" forcerange="-60 60"/>

    <!-- Right hand -->
    <general name="R_thumb_MCP_joint1_pos" joint="R_thumb_MCP_joint1" gaintype="fixed" biastype="affine" gainprm="800" biasprm="0 -800 -80" ctrllimited="true" ctrlrange="0 1.1" forcelimited="true" forcerange="-20 20"/>
    <general name="R_thumb_MCP_joint2_pos" joint="R_thumb_MCP_joint2" gaintype="fixed" biastype="affine" gainprm="800" biasprm="0 -800 -80" ctrllimited="true" ctrlrange="0 0.5" forcelimited="true" forcerange="-20 20"/>
    <general name="R_index_MCP_joint_pos" joint="R_index_MCP_joint" gaintype="fixed" biastype="affine" gainprm="800" biasprm="0 -800 -80" ctrllimited="true" ctrlrange="0 1.7" forcelimited="true" forcerange="-20 20"/>
    <general name="R_middle_MCP_joint_pos" joint="R_middle_MCP_joint" gaintype="fixed" biastype="affine" gainprm="800" biasprm="0 -800 -80" ctrllimited="true" ctrlrange="0 1.68" forcelimited="true" forcerange="-20 20"/>
    <general name="R_ring_MCP_joint_pos" joint="R_ring_MCP_joint" gaintype="fixed" biastype="affine" gainprm="800" biasprm="0 -800 -80" ctrllimited="true" ctrlrange="0 1.7" forcelimited="true" forcerange="-20 20"/>
    <general name="R_pinky_MCP_joint_pos" joint="R_pinky_MCP_joint" gaintype="fixed" biastype="affine" gainprm="800" biasprm="0 -800 -80" ctrllimited="true" ctrlrange="0 1.7" forcelimited="true" forcerange="-20 20"/>
  </actuator>
</mujoco>
