<?xml version="1.0" encoding="utf-8"?>
<!-- This URDF was automatically created by SolidWorks to URDF Exporter! Originally created by Stephen Brawner (brawner@gmail.com) 
     Commit Version: 1.6.0-4-g7f85cfe  Build Version: 1.6.7995.38578
     For more information, please see http://wiki.ros.org/sw_urdf_exporter -->
<robot
  name="r1_pro_with_hand">
  <mujoco>
        <compiler 
        meshdir="../meshes/" 
        balanceinertia="true" 
        discardvisual="false" />
  </mujoco>
  <link
    name="base_link">
    <inertial>
      <origin
        xyz="-0.049262 -8.8054E-05 0.18255"
        rpy="0 0 0" />
      <mass
        value="47.63" />
      <inertia
        ixx="1.5812"
        ixy="-1.0625E-05"
        ixz="0.053601"
        iyy="1.4648"
        iyz="5.7054E-06"
        izz="2.835" />
    </inertial>
    <visual>
      <origin
        xyz="0 0 0"
        rpy="0 0 0" />
      <geometry>
        <mesh
          filename="package://mobiman/urdf/r1_pro_with_hand/meshes/base_link.STL" />
      </geometry>
      <material
        name="">
        <color
          rgba="0.82353 0.82353 1 1" />
      </material>
    </visual>
    <collision>
      <origin
        xyz="0 0 0"
        rpy="0 0 0" />
      <geometry>
        <mesh
          filename="package://mobiman/urdf/r1_pro_with_hand/meshes/base_link.STL" />
      </geometry>
    </collision>
  </link>
  <link
    name="steer_motor_link1">
    <inertial>
      <origin
        xyz="7.7174E-06 -0.004623 -0.049428"
        rpy="0 0 0" />
      <mass
        value="1.5" />
      <inertia
        ixx="0.00022164"
        ixy="-3.529E-09"
        ixz="3.4267E-09"
        iyy="0.00032908"
        iyz="-7.5872E-08"
        izz="0.00015872" />
    </inertial>
    <visual>
      <origin
        xyz="0 0 0"
        rpy="0 0 0" />
      <geometry>
        <mesh
          filename="package://mobiman/urdf/r1_pro_with_hand/meshes/steer_motor_link1.STL" />
      </geometry>
      <material
        name="">
        <color
          rgba="0.82353 0.82353 1 1" />
      </material>
    </visual>
    <collision>
      <origin
        xyz="0 0 0"
        rpy="0 0 0" />
      <geometry>
        <mesh
          filename="package://mobiman/urdf/r1_pro_with_hand/meshes/steer_motor_link1.STL" />
      </geometry>
    </collision>
  </link>
  <joint
    name="steer_motor_joint1"
    type="revolute">
    <origin
      xyz="0.16897 0.28 0.15765"
      rpy="0 0 0" />
    <parent
      link="base_link" />
    <child
      link="steer_motor_link1" />
    <axis
      xyz="0 0 1" />
    <limit
      lower="-3.1416"
      upper="3.1416"
      effort="50"
      velocity="20" />
  </joint>
  <link
    name="wheel_motor_link1">
    <inertial>
      <origin
        xyz="1.6481E-10 -1.6203E-10 -9.455E-10"
        rpy="0 0 0" />
      <mass
        value="1.5" />
      <inertia
        ixx="0.0012628"
        ixy="1.0701E-10"
        ixz="5.7971E-09"
        iyy="0.0020893"
        iyz="1.2406E-09"
        izz="0.0012628" />
    </inertial>
    <visual>
      <origin
        xyz="0 0 0"
        rpy="0 0 0" />
      <geometry>
        <mesh
          filename="package://mobiman/urdf/r1_pro_with_hand/meshes/wheel_motor_link1.STL" />
      </geometry>
      <material
        name="">
        <color
          rgba="0.82353 0.82353 1 1" />
      </material>
    </visual>
    <collision>
      <origin
        xyz="0 0 0"
        rpy="0 0 0" />
      <geometry>
        <mesh
          filename="package://mobiman/urdf/r1_pro_with_hand/meshes/wheel_motor_link1.STL" />
      </geometry>
    </collision>
  </link>
  <joint
    name="wheel_motor_joint1"
    type="continuous">
    <origin
      xyz="0 0 -0.08765"
      rpy="0 0 0" />
    <parent
      link="steer_motor_link1" />
    <child
      link="wheel_motor_link1" />
    <axis
      xyz="0 1 0" />
  </joint>
  <link
    name="steer_motor_link2">
    <inertial>
      <origin
        xyz="6.044E-06 0.00010023 -0.052223"
        rpy="0 0 0" />
      <mass
        value="1.5" />
      <inertia
        ixx="0.0002535"
        ixy="-4.9113E-09"
        ixz="5.8918E-09"
        iyy="0.00037037"
        iyz="-2.9177E-07"
        izz="0.000163" />
    </inertial>
    <visual>
      <origin
        xyz="0 0 0"
        rpy="0 0 0" />
      <geometry>
        <mesh
          filename="package://mobiman/urdf/r1_pro_with_hand/meshes/steer_motor_link2.STL" />
      </geometry>
      <material
        name="">
        <color
          rgba="0.82353 0.82353 1 1" />
      </material>
    </visual>
    <collision>
      <origin
        xyz="0 0 0"
        rpy="0 0 0" />
      <geometry>
        <mesh
          filename="package://mobiman/urdf/r1_pro_with_hand/meshes/steer_motor_link2.STL" />
      </geometry>
    </collision>
  </link>
  <joint
    name="steer_motor_joint2"
    type="revolute">
    <origin
      xyz="0.16897 -0.28 0.15765"
      rpy="0 0 0" />
    <parent
      link="base_link" />
    <child
      link="steer_motor_link2" />
    <axis
      xyz="0 0 1" />
    <limit
      lower="-3.1416"
      upper="3.1416"
      effort="50"
      velocity="20" />
  </joint>
  <link
    name="wheel_motor_link2">
    <inertial>
      <origin
        xyz="1.6448E-10 -1.616E-10 -9.4549E-10"
        rpy="0 0 0" />
      <mass
        value="1.5" />
      <inertia
        ixx="0.0012628"
        ixy="1.0701E-10"
        ixz="5.7971E-09"
        iyy="0.0020893"
        iyz="1.2406E-09"
        izz="0.0012628" />
    </inertial>
    <visual>
      <origin
        xyz="0 0 0"
        rpy="0 0 0" />
      <geometry>
        <mesh
          filename="package://mobiman/urdf/r1_pro_with_hand/meshes/wheel_motor_link2.STL" />
      </geometry>
      <material
        name="">
        <color
          rgba="0.82353 0.82353 1 1" />
      </material>
    </visual>
    <collision>
      <origin
        xyz="0 0 0"
        rpy="0 0 0" />
      <geometry>
        <mesh
          filename="package://mobiman/urdf/r1_pro_with_hand/meshes/wheel_motor_link2.STL" />
      </geometry>
    </collision>
  </link>
  <joint
    name="wheel_motor_joint2"
    type="continuous">
    <origin
      xyz="0 0 -0.08765"
      rpy="0 0 0" />
    <parent
      link="steer_motor_link2" />
    <child
      link="wheel_motor_link2" />
    <axis
      xyz="0 1 0" />
  </joint>
  <link
    name="steer_motor_link3">
    <inertial>
      <origin
        xyz="-6.029E-06 -0.00010167 -0.052221"
        rpy="0 0 0" />
      <mass
        value="1.5" />
      <inertia
        ixx="0.0002535"
        ixy="-4.6767E-09"
        ixz="-3.5903E-09"
        iyy="0.00037036"
        iyz="2.9246E-07"
        izz="0.000163" />
    </inertial>
    <visual>
      <origin
        xyz="0 0 0"
        rpy="0 0 0" />
      <geometry>
        <mesh
          filename="package://mobiman/urdf/r1_pro_with_hand/meshes/steer_motor_link3.STL" />
      </geometry>
      <material
        name="">
        <color
          rgba="0.82353 0.82353 1 1" />
      </material>
    </visual>
    <collision>
      <origin
        xyz="0 0 0"
        rpy="0 0 0" />
      <geometry>
        <mesh
          filename="package://mobiman/urdf/r1_pro_with_hand/meshes/steer_motor_link3.STL" />
      </geometry>
    </collision>
  </link>
  <joint
    name="steer_motor_joint3"
    type="revolute">
    <origin
      xyz="-0.32703 0 0.15765"
      rpy="0 0 0" />
    <parent
      link="base_link" />
    <child
      link="steer_motor_link3" />
    <axis
      xyz="0 0 1" />
    <limit
      lower="-3.1416"
      upper="3.1416"
      effort="50"
      velocity="20" />
  </joint>
  <link
    name="wheel_motor_link3">
    <inertial>
      <origin
        xyz="-2.443E-09 1.4779E-12 5.1754E-12"
        rpy="0 0 0" />
      <mass
        value="1.5" />
      <inertia
        ixx="0.0012628"
        ixy="1.1439E-10"
        ixz="5.7894E-09"
        iyy="0.0020893"
        iyz="1.2052E-09"
        izz="0.0012628" />
    </inertial>
    <visual>
      <origin
        xyz="0 0 0"
        rpy="0 0 0" />
      <geometry>
        <mesh
          filename="package://mobiman/urdf/r1_pro_with_hand/meshes/wheel_motor_link3.STL" />
      </geometry>
      <material
        name="">
        <color
          rgba="0.82353 0.82353 1 1" />
      </material>
    </visual>
    <collision>
      <origin
        xyz="0 0 0"
        rpy="0 0 0" />
      <geometry>
        <mesh
          filename="package://mobiman/urdf/r1_pro_with_hand/meshes/wheel_motor_link3.STL" />
      </geometry>
    </collision>
  </link>
  <joint
    name="wheel_motor_joint3"
    type="continuous">
    <origin
      xyz="0 0 -0.08765"
      rpy="0 0 0" />
    <parent
      link="steer_motor_link3" />
    <child
      link="wheel_motor_link3" />
    <axis
      xyz="0 1 0" />
  </joint>
  <link
    name="torso_link1">
    <inertial>
      <origin
        xyz="0.00065636 0.0032244 0.23142"
        rpy="0 0 0" />
      <mass
        value="5.72" />
      <inertia
        ixx="0.10931"
        ixy="7.7894E-06"
        ixz="-0.00017473"
        iyy="0.10736"
        iyz="0.00013778"
        izz="0.0081222" />
    </inertial>
    <visual>
      <origin
        xyz="0 0 0"
        rpy="0 0 0" />
      <geometry>
        <mesh
          filename="package://mobiman/urdf/r1_pro_with_hand/meshes/torso_link1.STL" />
      </geometry>
      <material
        name="">
        <color
          rgba="0.82353 0.82353 1 1" />
      </material>
    </visual>
    <collision>
      <origin
        xyz="0 0 0"
        rpy="0 0 0" />
      <geometry>
        <mesh
          filename="package://mobiman/urdf/r1_pro_with_hand/meshes/torso_link1.STL" />
      </geometry>
    </collision>
  </link>
  <joint
    name="torso_joint1"
    type="revolute">
    <origin
      xyz="-0.079032 0 0.34265"
      rpy="0 0 0" />
    <parent
      link="base_link" />
    <child
      link="torso_link1" />
    <axis
      xyz="0 1 0" />
    <limit
      lower="-1.1345"
      upper="1.8326"
      effort="100"
      velocity="2.5" />
  </joint>
  <link
    name="torso_link2">
    <inertial>
      <origin
        xyz="0.0052517 0.014411 0.15711"
        rpy="0 0 0" />
      <mass
        value="3.5" />
      <inertia
        ixx="0.026081"
        ixy="-3.3436E-07"
        ixz="0.00024541"
        iyy="0.027574"
        iyz="4.2283E-07"
        izz="0.0018515" />
    </inertial>
    <visual>
      <origin
        xyz="0 0 0"
        rpy="0 0 0" />
      <geometry>
        <mesh
          filename="package://mobiman/urdf/r1_pro_with_hand/meshes/torso_link2.STL" />
      </geometry>
      <material
        name="">
        <color
          rgba="0.82353 0.82353 1 1" />
      </material>
    </visual>
    <collision>
      <origin
        xyz="0 0 0"
        rpy="0 0 0" />
      <geometry>
        <mesh
          filename="package://mobiman/urdf/r1_pro_with_hand/meshes/torso_link2.STL" />
      </geometry>
    </collision>
  </link>
  <joint
    name="torso_joint2"
    type="revolute">
    <origin
      xyz="0 0 0.4"
      rpy="0 0 0" />
    <parent
      link="torso_link1" />
    <child
      link="torso_link2" />
    <axis
      xyz="0 1 0" />
    <limit
      lower="-2.7925"
      upper="2.5307"
      effort="100"
      velocity="2.5" />
  </joint>
  <link
    name="torso_link3">
    <inertial>
      <origin
        xyz="-9.8337E-07 -0.0055146 0.020182"
        rpy="0 0 0" />
      <mass
        value="3.4" />
      <inertia
        ixx="0.0016099"
        ixy="3.5899E-07"
        ixz="2.5497E-07"
        iyy="0.0023011"
        iyz="1.367E-05"
        izz="0.0017027" />
    </inertial>
    <visual>
      <origin
        xyz="0 0 0"
        rpy="0 0 0" />
      <geometry>
        <mesh
          filename="package://mobiman/urdf/r1_pro_with_hand/meshes/torso_link3.STL" />
      </geometry>
      <material
        name="">
        <color
          rgba="0.82353 0.82353 1 1" />
      </material>
    </visual>
    <collision>
      <origin
        xyz="0 0 0"
        rpy="0 0 0" />
      <geometry>
        <mesh
          filename="package://mobiman/urdf/r1_pro_with_hand/meshes/torso_link3.STL" />
      </geometry>
    </collision>
  </link>
  <joint
    name="torso_joint3"
    type="revolute">
    <origin
      xyz="0 0.0001005 0.3"
      rpy="0 0 0" />
    <parent
      link="torso_link2" />
    <child
      link="torso_link3" />
    <axis
      xyz="0 -1 0" />
    <limit
      lower="-1.8326"
      upper="1.5708"
      effort="100"
      velocity="2.5" />
  </joint>
  <link
    name="torso_link4">
    <inertial>
      <origin
        xyz="0.0049601 -1.2497E-05 0.21237"
        rpy="0 0 0" />
      <mass
        value="5" />
      <inertia
        ixx="0.026836"
        ixy="1.3048E-05"
        ixz="-0.00014074"
        iyy="0.013023"
        iyz="4.6641E-07"
        izz="0.021541" />
    </inertial>
    <visual>
      <origin
        xyz="0 0 0"
        rpy="0 0 0" />
      <geometry>
        <mesh
          filename="package://mobiman/urdf/r1_pro_with_hand/meshes/torso_link4.STL" />
      </geometry>
      <material
        name="">
        <color
          rgba="0.82353 0.82353 1 1" />
      </material>
    </visual>
    <collision>
      <origin
        xyz="0 0 0"
        rpy="0 0 0" />
      <geometry>
        <mesh
          filename="package://mobiman/urdf/r1_pro_with_hand/meshes/torso_link4.STL" />
      </geometry>
    </collision>
  </link>
  <joint
    name="torso_joint4"
    type="revolute">
    <origin
      xyz="0 -0.00010015 0.09962"
      rpy="0 0 0" />
    <parent
      link="torso_link3" />
    <child
      link="torso_link4" />
    <axis
      xyz="0 0 1" />
    <limit
      lower="-3.0543"
      upper="3.0543"
      effort="100"
      velocity="2.5" />
  </joint>
  <link
    name="zed_link">
    <inertial>
      <origin
        xyz="0.060004 0.015906 -0.068413"
        rpy="0 0 0" />
      <mass
        value="2.05" />
      <inertia
        ixx="0.010375"
        ixy="1.8965E-07"
        ixz="1.3342E-08"
        iyy="0.014618"
        iyz="0.00028961"
        izz="0.012229" />
    </inertial>
    <visual>
      <origin
        xyz="0 0 0"
        rpy="0 0 0" />
      <geometry>
        <mesh
          filename="package://mobiman/urdf/r1_pro_with_hand/meshes/zed_link.STL" />
      </geometry>
      <material
        name="">
        <color
          rgba="0.82353 0.82353 1 1" />
      </material>
    </visual>
    <collision>
      <origin
        xyz="0 0 0"
        rpy="0 0 0" />
      <geometry>
        <mesh
          filename="package://mobiman/urdf/r1_pro_with_hand/meshes/zed_link.STL" />
      </geometry>
    </collision>
  </link>
  <joint
    name="zed_joint"
    type="fixed">
    <origin
      xyz="0.065511 0.060003 0.47598"
      rpy="-1.9199 0 -1.5708" />
    <parent
      link="torso_link4" />
    <child
      link="zed_link" />
    <axis
      xyz="0 0 0" />
  </joint>
  <link
    name="left_arm_base_link">
    <inertial>
      <origin
        xyz="0.00026981 0.034587 1.3734E-08"
        rpy="0 0 0" />
      <mass
        value="1.48" />
      <inertia
        ixx="0.0010298"
        ixy="5.2194E-06"
        ixz="-1.2182E-07"
        iyy="0.0014076"
        iyz="-3.9334E-09"
        izz="0.0010201" />
    </inertial>
    <visual>
      <origin
        xyz="0 0 0"
        rpy="0 0 0" />
      <geometry>
        <mesh
          filename="package://mobiman/urdf/r1_pro_with_hand/meshes/left_arm_base_link.STL" />
      </geometry>
      <material
        name="">
        <color
          rgba="0.82353 0.82353 1 1" />
      </material>
    </visual>
    <collision>
      <origin
        xyz="0 0 0"
        rpy="0 0 0" />
      <geometry>
        <mesh
          filename="package://mobiman/urdf/r1_pro_with_hand/meshes/left_arm_base_link.STL" />
      </geometry>
    </collision>
  </link>
  <joint
    name="left_arm_base_joint"
    type="fixed">
    <origin
      xyz="-0.00048618 0.097234 0.30302"
      rpy="0 0 0" />
    <parent
      link="torso_link4" />
    <child
      link="left_arm_base_link" />
    <axis
      xyz="0 0 0" />
  </joint>
  <link
    name="left_arm_link1">
    <inertial>
      <origin
        xyz="0.00042258 0.074131 7.9156E-05"
        rpy="0 0 0" />
      <mass
        value="1.135" />
      <inertia
        ixx="0.00061603"
        ixy="-1.1635E-06"
        ixz="-6.9725E-07"
        iyy="0.00030259"
        iyz="-6.2894E-07"
        izz="0.00047136" />
    </inertial>
    <visual>
      <origin
        xyz="0 0 0"
        rpy="0 0 0" />
      <geometry>
        <mesh
          filename="package://mobiman/urdf/r1_pro_with_hand/meshes/left_arm_link1.STL" />
      </geometry>
      <material
        name="">
        <color
          rgba="0.82353 0.82353 1 1" />
      </material>
    </visual>
    <collision>
      <origin
        xyz="0 0 0"
        rpy="0 0 0" />
      <geometry>
        <mesh
          filename="package://mobiman/urdf/r1_pro_with_hand/meshes/left_arm_link1.STL" />
      </geometry>
    </collision>
  </link>
  <joint
    name="left_arm_joint1"
    type="revolute">
    <origin
      xyz="0 0.0735 0"
      rpy="0 0 0" />
    <parent
      link="left_arm_base_link" />
    <child
      link="left_arm_link1" />
    <axis
      xyz="0 1 0" />
    <limit
      lower="-4.4506"
      upper="1.3090"
      effort="55"
      velocity="7.1209" />
  </joint>
  <link
    name="left_arm_link2">
    <inertial>
      <origin
        xyz="-0.026826 -0.0040392 -0.031835"
        rpy="0 0 0" />
      <mass
        value="0.92" />
      <inertia
        ixx="0.00037378"
        ixy="-7.5909E-07"
        ixz="2.9042E-06"
        iyy="0.00033872"
        iyz="1.2166E-05"
        izz="0.00032361" />
    </inertial>
    <visual>
      <origin
        xyz="0 0 0"
        rpy="0 0 0" />
      <geometry>
        <mesh
          filename="package://mobiman/urdf/r1_pro_with_hand/meshes/left_arm_link2.STL" />
      </geometry>
      <material
        name="">
        <color
          rgba="0.82353 0.82353 1 1" />
      </material>
    </visual>
    <collision>
      <origin
        xyz="0 0 0"
        rpy="0 0 0" />
      <geometry>
        <mesh
          filename="package://mobiman/urdf/r1_pro_with_hand/meshes/left_arm_link2.STL" />
      </geometry>
    </collision>
  </link>
  <joint
    name="left_arm_joint2"
    type="revolute">
    <origin
      xyz="0.025012 0.081265 0"
      rpy="0 0 0" />
    <parent
      link="left_arm_link1" />
    <child
      link="left_arm_link2" />
    <axis
      xyz="1 0 0" />
    <limit
      lower="-0.1745"
      upper="3.1416"
      effort="55"
      velocity="7.1209" />
  </joint>
  <link
    name="left_arm_link3">
    <inertial>
      <origin
        xyz="0.0053849 -0.00086892 -0.1126"
        rpy="0 0 0" />
      <mass
        value="1.245" />
      <inertia
        ixx="0.00072339"
        ixy="-3.3477E-06"
        ixz="-0.00012824"
        iyy="0.00073856"
        iyz="-8.3574E-06"
        izz="0.00037352" />
    </inertial>
    <visual>
      <origin
        xyz="0 0 0"
        rpy="0 0 0" />
      <geometry>
        <mesh
          filename="package://mobiman/urdf/r1_pro_with_hand/meshes/left_arm_link3.STL" />
      </geometry>
      <material
        name="">
        <color
          rgba="0.82353 0.82353 1 1" />
      </material>
    </visual>
    <collision>
      <origin
        xyz="0 0 0"
        rpy="0 0 0" />
      <geometry>
        <mesh
          filename="package://mobiman/urdf/r1_pro_with_hand/meshes/left_arm_link3.STL" />
      </geometry>
    </collision>
  </link>
  <joint
    name="left_arm_joint3"
    type="revolute">
    <origin
      xyz="-0.025012 0 -0.1155"
      rpy="0 0 0" />
    <parent
      link="left_arm_link2" />
    <child
      link="left_arm_link3" />
    <axis
      xyz="0 0 1" />
    <limit
      lower="-2.356196"
      upper="2.356196"
      effort="25"
      velocity="8.3776" />
  </joint>
  <link
    name="left_arm_link4">
    <inertial>
      <origin
        xyz="-0.0011018 -0.036243 -0.042164"
        rpy="0 0 0" />
      <mass
        value="0.827" />
      <inertia
        ixx="0.00013884"
        ixy="7.8394E-08"
        ixz="3.5926E-06"
        iyy="0.00019751"
        iyz="1.4227E-06"
        izz="0.00010229" />
    </inertial>
    <visual>
      <origin
        xyz="0 0 0"
        rpy="0 0 0" />
      <geometry>
        <mesh
          filename="package://mobiman/urdf/r1_pro_with_hand/meshes/left_arm_link4.STL" />
      </geometry>
      <material
        name="">
        <color
          rgba="0.82353 0.82353 1 1" />
      </material>
    </visual>
    <collision>
      <origin
        xyz="0 0 0"
        rpy="0 0 0" />
      <geometry>
        <mesh
          filename="package://mobiman/urdf/r1_pro_with_hand/meshes/left_arm_link4.STL" />
      </geometry>
    </collision>
  </link>
  <joint
    name="left_arm_joint4"
    type="revolute">
    <origin
      xyz="0 0.035065 -0.1945"
      rpy="0 0 0" />
    <parent
      link="left_arm_link3" />
    <child
      link="left_arm_link4" />
    <axis
      xyz="0 1 0" />
    <limit
      lower="-1.7453"
      upper="0.3491"
      effort="25"
      velocity="8.3776" />
  </joint>
  <link
    name="left_arm_link5">
    <inertial>
      <origin
        xyz="3.7881E-07 -0.0028035 -0.062981"
        rpy="0 0 0" />
      <mass
        value="0.939" />
      <inertia
        ixx="0.00070496"
        ixy="1.4329E-08"
        ixz="-2.9036E-09"
        iyy="0.00067006"
        iyz="-5.1951E-05"
        izz="0.00032998" />
    </inertial>
    <visual>
      <origin
        xyz="0 0 0"
        rpy="0 0 0" />
      <geometry>
        <mesh
          filename="package://mobiman/urdf/r1_pro_with_hand/meshes/left_arm_link5.STL" />
      </geometry>
      <material
        name="">
        <color
          rgba="0.82353 0.82353 1 1" />
      </material>
    </visual>
    <collision>
      <origin
        xyz="0 0 0"
        rpy="0 0 0" />
      <geometry>
        <mesh
          filename="package://mobiman/urdf/r1_pro_with_hand/meshes/left_arm_link5.STL" />
      </geometry>
    </collision>
  </link>
  <joint
    name="left_arm_joint5"
    type="revolute">
    <origin
      xyz="0 -0.035065 -0.095"
      rpy="0 0 0" />
    <parent
      link="left_arm_link4" />
    <child
      link="left_arm_link5" />
    <axis
      xyz="0 0 1" />
    <limit
      lower="-2.356196"
      upper="2.356196"
      effort="18"
      velocity="10.4720" />
  </joint>
  <link
    name="left_arm_link6">
    <inertial>
      <origin
        xyz="0.0017919 0.027487 0.00025471"
        rpy="0 0 0" />
      <mass
        value="0.527" />
      <inertia
        ixx="8.5442E-05"
        ixy="-1.5351E-07"
        ixz="8.3797E-07"
        iyy="8.1186E-05"
        iyz="-2.1972E-08"
        izz="8.2736E-05" />
    </inertial>
    <visual>
      <origin
        xyz="0 0 0"
        rpy="0 0 0" />
      <geometry>
        <mesh
          filename="package://mobiman/urdf/r1_pro_with_hand/meshes/left_arm_link6.STL" />
      </geometry>
      <material
        name="">
        <color
          rgba="0.82353 0.82353 1 1" />
      </material>
    </visual>
    <collision>
      <origin
        xyz="0 0 0"
        rpy="0 0 0" />
      <geometry>
        <mesh
          filename="package://mobiman/urdf/r1_pro_with_hand/meshes/left_arm_link6.STL" />
      </geometry>
    </collision>
  </link>
  <joint
    name="left_arm_joint6"
    type="revolute">
    <origin
      xyz="0 -0.028 -0.16305"
      rpy="0 0 0" />
    <parent
      link="left_arm_link5" />
    <child
      link="left_arm_link6" />
    <axis
      xyz="0 1 0" />
    <limit
      lower="-1.047198"
      upper="1.047198"
      effort="18"
      velocity="10.4720" />
  </joint>
  <link
    name="left_arm_link7">
    <inertial>
      <origin
        xyz="-0.022945 8.4007E-07 -0.056525"
        rpy="0 0 0" />
      <mass
        value="0.185" />
      <inertia
        ixx="4.2564E-05"
        ixy="-2.1577E-09"
        ixz="-6.9368E-06"
        iyy="4.5515E-05"
        iyz="-1.9389E-09"
        izz="4.7946E-05" />
    </inertial>
    <visual>
      <origin
        xyz="0 0 0"
        rpy="0 0 0" />
      <geometry>
        <mesh
          filename="package://mobiman/urdf/r1_pro_with_hand/meshes/left_arm_link7.STL" />
      </geometry>
      <material
        name="">
        <color
          rgba="0.82353 0.82353 1 1" />
      </material>
    </visual>
    <collision>
      <origin
        xyz="0 0 0"
        rpy="0 0 0" />
      <geometry>
        <mesh
          filename="package://mobiman/urdf/r1_pro_with_hand/meshes/left_arm_link7.STL" />
      </geometry>
    </collision>
  </link>
  <joint
    name="left_arm_joint7"
    type="revolute">
    <origin
      xyz="0.0295 0.028 0"
      rpy="0 0 0" />
    <parent
      link="left_arm_link6" />
    <child
      link="left_arm_link7" />
    <axis
      xyz="1 0 0" />
    <limit
      lower="-1.5708"
      upper="1.5708"
      effort="18"
      velocity="10.4720" />
  </joint>
  <link
    name="L_hand_base_link">
    <inertial>
      <origin
        xyz="-0.0010903 -0.00078833 -0.025733"
        rpy="0 0 0" />
      <mass
        value="0.052435" />
      <inertia
        ixx="2.3131E-05"
        ixy="-2.1744E-07"
        ixz="-7.3326E-07"
        iyy="2.7075E-05"
        iyz="-8.4801E-07"
        izz="2.481E-05" />
    </inertial>
    <visual>
      <origin
        xyz="0 0 0"
        rpy="0 0 0" />
      <geometry>
        <mesh
          filename="package://mobiman/urdf/r1_pro_with_hand/meshes/L_hand_base_link.STL" />
      </geometry>
      <material
        name="">
        <color
          rgba="1 1 1 1" />
      </material>
    </visual>
    <collision>
      <origin
        xyz="0 0 0"
        rpy="0 0 0" />
      <geometry>
        <mesh
          filename="package://mobiman/urdf/r1_pro_with_hand/meshes/L_hand_base_link.STL" />
      </geometry>
    </collision>
  </link>
  <joint
    name="L_hand_base_joint"
    type="fixed">
    <origin
      xyz="-0.0295 0 -0.084"
      rpy="0 0 0" />
    <parent
      link="left_arm_link7" />
    <child
      link="L_hand_base_link" />
    <axis
      xyz="0 0 0" />
  </joint>
  <link
    name="L_hand_palm_link">
    <inertial>
      <origin
        xyz="-0.0029601 0.022034 -0.00017712"
        rpy="0 0 0" />
      <mass
        value="0.043564" />
      <inertia
        ixx="1.0367E-05"
        ixy="-1.2704E-08"
        ixz="-2.1105E-07"
        iyy="1.1144E-05"
        iyz="-2.0979E-07"
        izz="1.8332E-06" />
    </inertial>
    <visual>
      <origin
        xyz="0 0 0"
        rpy="0 0 0" />
      <geometry>
        <mesh
          filename="package://mobiman/urdf/r1_pro_with_hand/meshes/L_hand_palm_link.STL" />
      </geometry>
      <material
        name="">
        <color
          rgba="1 1 1 1" />
      </material>
    </visual>
    <collision>
      <origin
        xyz="0 0 0"
        rpy="0 0 0" />
      <geometry>
        <mesh
          filename="package://mobiman/urdf/r1_pro_with_hand/meshes/L_hand_palm_link.STL" />
      </geometry>
    </collision>
  </link>
  <joint
    name="L_hand_palm_joint"
    type="fixed">
    <origin
      xyz="0.00048551 -0.02096 -0.082692"
      rpy="0 0 0" />
    <parent
      link="L_hand_base_link" />
    <child
      link="L_hand_palm_link" />
    <axis
      xyz="0 0 0" />
  </joint>
  <link
    name="L_thumb_proximal_base">
    <inertial>
      <origin
        xyz="0.00357733135671393 -0.00251129458369284 -0.000669320389664607"
        rpy="0 0 0" />
      <mass
        value="0.00171905407931692" />
      <inertia
        ixx="6.45811972490844E-08"
        ixy="1.49531298183286E-08"
        ixz="2.03323708760113E-09"
        iyy="5.58356617801001E-08"
        iyz="-2.23145485059158E-09"
        izz="6.01049566683397E-08" />
    </inertial>
    <visual>
      <origin
        xyz="0 0 0"
        rpy="0 0 0" />
      <geometry>
        <mesh
          filename="package://mobiman/urdf/r1_pro_with_hand/meshes/L_thumb_proximal_base.STL" />
      </geometry>
      <material
        name="">
        <color
          rgba="1 1 1 1" />
      </material>
    </visual>
    <collision>
      <origin
        xyz="0 0 0"
        rpy="0 0 0" />
      <geometry>
        <mesh
          filename="package://mobiman/urdf/r1_pro_with_hand/meshes/L_thumb_proximal_base.STL" />
      </geometry>
    </collision>
  </link>
  <joint
    name="L_thumb_MCP_joint1"
    type="revolute">
    <origin
      xyz="0.02045 -0.01696 -0.0606"
      rpy="0 0 0" />
    <parent
      link="L_hand_base_link" />
    <child
      link="L_thumb_proximal_base" />
    <axis
      xyz="0 0 -1" />
    <limit
      lower="0"
      upper="1.1"
      effort="50"
      velocity="1" />
  </joint>
  <link
    name="L_thumb_proximal">
    <inertial>
      <origin
        xyz="-0.000292493455658197 -0.0213780649639438 -0.0146404445273511"
        rpy="0 0 0" />
      <mass
        value="0.00716305672165334" />
      <inertia
        ixx="2.83787775945407E-06"
        ixy="2.97427781504765E-10"
        ixz="1.41334270068087E-09"
        iyy="1.62565308351993E-06"
        iyz="-7.766964852057E-07"
        izz="1.73803132188643E-06" />
    </inertial>
    <visual>
      <origin
        xyz="0 0 0"
        rpy="0 0 0" />
      <geometry>
        <mesh
          filename="package://mobiman/urdf/r1_pro_with_hand/meshes/L_thumb_proximal.STL" />
      </geometry>
      <material
        name="">
        <color
          rgba="1 1 1 1" />
      </material>
    </visual>
    <collision>
      <origin
        xyz="0 0 0"
        rpy="0 0 0" />
      <geometry>
        <mesh
          filename="package://mobiman/urdf/r1_pro_with_hand/meshes/L_thumb_proximal.STL" />
      </geometry>
    </collision>
  </link>
  <joint
    name="L_thumb_MCP_joint2"
    type="revolute">
    <origin
      xyz="0.0086232 -0.0076086 0.00075003"
      rpy="0 0 0.84783" />
    <parent
      link="L_thumb_proximal_base" />
    <child
      link="L_thumb_proximal" />
    <axis
      xyz="1 0 0" />
    <limit
      lower="0"
      upper="0.5"
      effort="50"
      velocity="1" />
  </joint>
  <link
    name="L_thumb_intermediate">
    <inertial>
      <origin
        xyz="-9.42605783291334E-05 -0.00765673423106875 -0.00664960101630119"
        rpy="0 0 0" />
      <mass
        value="0.0040934495127094" />
      <inertia
        ixx="4.60452739774496E-07"
        ixy="-5.42269466688825E-12"
        ixz="-7.57458885091115E-12"
        iyy="3.92994962745689E-07"
        iyz="-8.86886090359123E-08"
        izz="3.09641858581993E-07" />
    </inertial>
    <visual>
      <origin
        xyz="0 0 0"
        rpy="0 0 0" />
      <geometry>
        <mesh
          filename="package://mobiman/urdf/r1_pro_with_hand/meshes/L_thumb_intermediate.STL" />
      </geometry>
      <material
        name="">
        <color
          rgba="1 1 1 1" />
      </material>
    </visual>
    <collision>
      <origin
        xyz="0 0 0"
        rpy="0 0 0" />
      <geometry>
        <mesh
          filename="package://mobiman/urdf/r1_pro_with_hand/meshes/L_thumb_intermediate.STL" />
      </geometry>
    </collision>
  </link>
  <joint
    name="L_thumb_PIP_joint"
    type="revolute">
    <origin
      xyz="0.0001 -0.043972 -0.030075"
      rpy="0 0 0" />
    <parent
      link="L_thumb_proximal" />
    <child
      link="L_thumb_intermediate" />
    <axis
      xyz="1 0 0" />
    <limit
      lower="0"
      upper="1"
      effort="50"
      velocity="1" />
    <mimic 
        joint="L_thumb_MCP_joint2"
        multiplier="1.6"
        offset="0" />
  </joint>
  <link
    name="L_thumb_distal">
    <inertial>
      <origin
        xyz="-3.4070296371369E-06 -0.00857257301794334 -0.00630127553409565"
        rpy="0 0 0" />
      <mass
        value="0.00330864079274024" />
      <inertia
        ixx="1.96165933712553E-07"
        ixy="7.45324689365921E-11"
        ixz="1.34504702101933E-10"
        iyy="1.50839490044667E-07"
        iyz="-5.31537560458138E-08"
        izz="1.21429447703053E-07" />
    </inertial>
    <visual>
      <origin
        xyz="0 0 0"
        rpy="0 0 0" />
      <geometry>
        <mesh
          filename="package://mobiman/urdf/r1_pro_with_hand/meshes/L_thumb_distal.STL" />
      </geometry>
      <material
        name="">
        <color
          rgba="1 1 1 1" />
      </material>
    </visual>
    <collision>
      <origin
        xyz="0 0 0"
        rpy="0 0 0" />
      <geometry>
        <mesh
          filename="package://mobiman/urdf/r1_pro_with_hand/meshes/L_thumb_distal.STL" />
      </geometry>
    </collision>
  </link>
  <joint
    name="L_thumb_DIP_joint"
    type="revolute">
    <origin
      xyz="-0.0001 -0.017066 -0.019311"
      rpy="0 0 0" />
    <parent
      link="L_thumb_intermediate" />
    <child
      link="L_thumb_distal" />
    <axis
      xyz="1 0 0" />
    <limit
      lower="0"
      upper="1.2"
      effort="50"
      velocity="1" />
    <mimic 
        joint="L_thumb_MCP_joint2"
        multiplier="2.4"
        offset="0" />
  </joint>
  <link
    name="L_index_proximal">
    <inertial>
      <origin
        xyz="-2.89286569699065E-09 -0.00171709287184449 -0.0129689231007696"
        rpy="0 0 0" />
      <mass
        value="0.000436731060950618" />
      <inertia
        ixx="3.87916631112751E-08"
        ixy="-2.68985589587214E-15"
        ixz="-5.58649454466455E-14"
        iyy="3.83561240024409E-08"
        iyz="8.62028609592021E-09"
        izz="4.88141452669615E-09" />
    </inertial>
    <visual>
      <origin
        xyz="0 0 0"
        rpy="0 0 0" />
      <geometry>
        <mesh
          filename="package://mobiman/urdf/r1_pro_with_hand/meshes/L_index_proximal.STL" />
      </geometry>
      <material
        name="">
        <color
          rgba="1 1 1 1" />
      </material>
    </visual>
    <collision>
      <origin
        xyz="0 0 0"
        rpy="0 0 0" />
      <geometry>
        <mesh
          filename="package://mobiman/urdf/r1_pro_with_hand/meshes/L_index_proximal.STL" />
      </geometry>
    </collision>
  </link>
  <joint
    name="L_index_MCP_joint"
    type="revolute">
    <origin
      xyz="0.026272 0.00028494 -0.13674"
      rpy="0 -0.034911 0" />
    <parent
      link="L_hand_base_link" />
    <child
      link="L_index_proximal" />
    <axis
      xyz="-1 0 0" />
    <limit
      lower="0"
      upper="1.7"
      effort="50"
      velocity="1" />
  </joint>
  <link
    name="L_index_distal">
    <inertial>
      <origin
        xyz="-1.63033037459126E-07 0.00188901548915552 -0.0194852403234491"
        rpy="0 0 0" />
      <mass
        value="0.00463375297256126" />
      <inertia
        ixx="7.84452048922784E-07"
        ixy="2.91748623921331E-12"
        ixz="-1.2784483948053E-14"
        iyy="7.60190901783576E-07"
        iyz="-1.02904087791176E-07"
        izz="9.90744738989579E-08" />
    </inertial>
    <visual>
      <origin
        xyz="0 0 0"
        rpy="0 0 0" />
      <geometry>
        <mesh
          filename="package://mobiman/urdf/r1_pro_with_hand/meshes/L_index_distal.STL" />
      </geometry>
      <material
        name="">
        <color
          rgba="1 1 1 1" />
      </material>
    </visual>
    <collision>
      <origin
        xyz="0 0 0"
        rpy="0 0 0" />
      <geometry>
        <mesh
          filename="package://mobiman/urdf/r1_pro_with_hand/meshes/L_index_distal.STL" />
      </geometry>
    </collision>
  </link>
  <joint
    name="L_index_DIP_joint"
    type="revolute">
    <origin
      xyz="0 -0.0027965 -0.03201"
      rpy="0 0 0" />
    <parent
      link="L_index_proximal" />
    <child
      link="L_index_distal" />
    <axis
      xyz="-1 0 0" />
    <limit
      lower="0"
      upper="1.6"
      effort="50"
      velocity="1" />
    <mimic 
        joint="L_index_MCP_joint"
        multiplier="1"
        offset="0" />
  </joint>
  <link
    name="L_middle_proximal">
    <inertial>
      <origin
        xyz="-2.7348374675995E-09 -0.00171709061780642 -0.0129689216303208"
        rpy="0 0 0" />
      <mass
        value="0.000436731045559847" />
      <inertia
        ixx="3.87916665197835E-08"
        ixy="-2.24661558989964E-15"
        ixz="-5.59516583938083E-14"
        iyy="3.83561250704983E-08"
        iyz="8.62029100705478E-09"
        izz="4.88141684840407E-09" />
    </inertial>
    <visual>
      <origin
        xyz="0 0 0"
        rpy="0 0 0" />
      <geometry>
        <mesh
          filename="package://mobiman/urdf/r1_pro_with_hand/meshes/L_middle_proximal.STL" />
      </geometry>
      <material
        name="">
        <color
          rgba="1 1 1 1" />
      </material>
    </visual>
    <collision>
      <origin
        xyz="0 0 0"
        rpy="0 0 0" />
      <geometry>
        <mesh
          filename="package://mobiman/urdf/r1_pro_with_hand/meshes/L_middle_proximal.STL" />
      </geometry>
    </collision>
  </link>
  <joint
    name="L_middle_MCP_joint"
    type="revolute">
    <origin
      xyz="0.0069507 0.00028503 -0.1371"
      rpy="0 0 0" />
    <parent
      link="L_hand_base_link" />
    <child
      link="L_middle_proximal" />
    <axis
      xyz="-1 0 0" />
    <limit
      lower="0"
      upper="1.68"
      effort="50"
      velocity="1" />
  </joint>
  <link
    name="L_middle_distal">
    <inertial>
      <origin
        xyz="-1.18887767464049E-07 0.00150375479035733 -0.0209788157895908"
        rpy="0 0 0" />
      <mass
        value="0.00500331471124545" />
      <inertia
        ixx="9.68379980272088E-07"
        ixy="3.24999840086695E-12"
        ixz="1.00558551999071E-12"
        iyy="9.3769172756647E-07"
        iyz="-1.32754344355808E-07"
        izz="1.11224977423711E-07" />
    </inertial>
    <visual>
      <origin
        xyz="0 0 0"
        rpy="0 0 0" />
      <geometry>
        <mesh
          filename="package://mobiman/urdf/r1_pro_with_hand/meshes/L_middle_distal.STL" />
      </geometry>
      <material
        name="">
        <color
          rgba="1 1 1 1" />
      </material>
    </visual>
    <collision>
      <origin
        xyz="0 0 0"
        rpy="0 0 0" />
      <geometry>
        <mesh
          filename="package://mobiman/urdf/r1_pro_with_hand/meshes/L_middle_distal.STL" />
      </geometry>
    </collision>
  </link>
  <joint
    name="L_middle_DIP_joint"
    type="revolute">
    <origin
      xyz="0 -0.0027965 -0.03201"
      rpy="0 0 0" />
    <parent
      link="L_middle_proximal" />
    <child
      link="L_middle_distal" />
    <axis
      xyz="-1 0 0" />
    <limit
      lower="0"
      upper="1.6"
      effort="50"
      velocity="1" />
    <mimic 
        joint="L_middle_MCP_joint"
        multiplier="1"
        offset="0" />
  </joint>
  <link
    name="L_ring_proximal">
    <inertial>
      <origin
        xyz="-2.51456905298042E-09 -0.00171708750382257 -0.0129689198708878"
        rpy="0 0 0" />
      <mass
        value="0.000436731022330395" />
      <inertia
        ixx="3.87916692571515E-08"
        ixy="-1.62993462850508E-15"
        ixz="-5.60675600191193E-14"
        iyy="3.83561243243846E-08"
        iyz="8.6202976994142E-09"
        izz="4.88142030029159E-09" />
    </inertial>
    <visual>
      <origin
        xyz="0 0 0"
        rpy="0 0 0" />
      <geometry>
        <mesh
          filename="package://mobiman/urdf/r1_pro_with_hand/meshes/L_ring_proximal.STL" />
      </geometry>
      <material
        name="">
        <color
          rgba="1 1 1 1" />
      </material>
    </visual>
    <collision>
      <origin
        xyz="0 0 0"
        rpy="0 0 0" />
      <geometry>
        <mesh
          filename="package://mobiman/urdf/r1_pro_with_hand/meshes/L_ring_proximal.STL" />
      </geometry>
    </collision>
  </link>
  <joint
    name="L_ring_MCP_joint"
    type="revolute">
    <origin
      xyz="-0.012278 0.00028511 -0.1366"
      rpy="0 0.052355 0" />
    <parent
      link="L_hand_base_link" />
    <child
      link="L_ring_proximal" />
    <axis
      xyz="-1 0 0" />
    <limit
      lower="0"
      upper="1.7"
      effort="50"
      velocity="1" />
  </joint>
  <link
    name="L_ring_distal">
    <inertial>
      <origin
        xyz="-1.60648082170312E-07 0.00188902153266679 -0.0194851866360107"
        rpy="0 0 0" />
      <mass
        value="0.00463375117556708" />
      <inertia
        ixx="7.8445158705104E-07"
        ixy="2.79807347500614E-12"
        ixz="2.92107799834708E-13"
        iyy="7.60190522779757E-07"
        iyz="-1.02904200867037E-07"
        izz="9.90744714294374E-08" />
    </inertial>
    <visual>
      <origin
        xyz="0 0 0"
        rpy="0 0 0" />
      <geometry>
        <mesh
          filename="package://mobiman/urdf/r1_pro_with_hand/meshes/L_ring_distal.STL" />
      </geometry>
      <material
        name="">
        <color
          rgba="1 1 1 1" />
      </material>
    </visual>
    <collision>
      <origin
        xyz="0 0 0"
        rpy="0 0 0" />
      <geometry>
        <mesh
          filename="package://mobiman/urdf/r1_pro_with_hand/meshes/L_ring_distal.STL" />
      </geometry>
    </collision>
  </link>
  <joint
    name="L_ring_DIP_joint"
    type="revolute">
    <origin
      xyz="0 -0.0027965 -0.03201"
      rpy="0 0 0" />
    <parent
      link="L_ring_proximal" />
    <child
      link="L_ring_distal" />
    <axis
      xyz="-1 0 0" />
    <limit
      lower="0"
      upper="1.6"
      effort="50"
      velocity="1" />
    <mimic 
        joint="L_ring_MCP_joint"
        multiplier="1"
        offset="0" />
  </joint>
  <link
    name="L_pinky_proximal">
    <inertial>
      <origin
        xyz="0 0 0"
        rpy="0 0 0" />
      <mass
        value="0.004404" />
      <inertia
        ixx="6.5597E-07"
        ixy="4.3193E-13"
        ixz="2.6692E-13"
        iyy="6.2552E-07"
        iyz="6.4015E-09"
        izz="2.1898E-07" />
    </inertial>
    <visual>
      <origin
        xyz="0 0 0"
        rpy="0 0 0" />
      <geometry>
        <mesh
          filename="package://mobiman/urdf/r1_pro_with_hand/meshes/L_pinky_proximal.STL" />
      </geometry>
      <material
        name="">
        <color
          rgba="1 1 1 1" />
      </material>
    </visual>
    <collision>
      <origin
        xyz="0 0 0"
        rpy="0 0 0" />
      <geometry>
        <mesh
          filename="package://mobiman/urdf/r1_pro_with_hand/meshes/L_pinky_proximal.STL" />
      </geometry>
    </collision>
  </link>
  <joint
    name="L_pinky_MCP_joint"
    type="revolute">
    <origin
      xyz="-0.031454 0.0002852 -0.13509"
      rpy="0 0.10472 0" />
    <parent
      link="L_hand_base_link" />
    <child
      link="L_pinky_proximal" />
    <axis
      xyz="-1 0 0" />
    <limit
      lower="0"
      upper="1.7"
      effort="50"
      velocity="1" />
  </joint>
  <link
    name="L_pinky_distal">
    <inertial>
      <origin
        xyz="-1.13071461665948E-07 0.00226828985898259 -0.0159775512818892"
        rpy="0 0 0" />
      <mass
        value="0.00370409154022854" />
      <inertia
        ixx="4.43371632532944E-07"
        ixy="2.29403270159531E-12"
        ixz="-1.51419931872125E-12"
        iyy="4.29885040390962E-07"
        iyz="-5.60518600319337E-08"
        izz="7.300448915623E-08" />
    </inertial>
    <visual>
      <origin
        xyz="0 0 0"
        rpy="0 0 0" />
      <geometry>
        <mesh
          filename="package://mobiman/urdf/r1_pro_with_hand/meshes/L_pinky_distal.STL" />
      </geometry>
      <material
        name="">
        <color
          rgba="1 1 1 1" />
      </material>
    </visual>
    <collision>
      <origin
        xyz="0 0 0"
        rpy="0 0 0" />
      <geometry>
        <mesh
          filename="package://mobiman/urdf/r1_pro_with_hand/meshes/L_pinky_distal.STL" />
      </geometry>
    </collision>
  </link>
  <joint
    name="L_pinky_DIP_joint"
    type="revolute">
    <origin
      xyz="0 -0.0027965 -0.03201"
      rpy="0 0 0" />
    <parent
      link="L_pinky_proximal" />
    <child
      link="L_pinky_distal" />
    <axis
      xyz="-1 0 0" />
    <limit
      lower="0"
      upper="1.6"
      effort="50"
      velocity="1" />
    <mimic 
        joint="L_pinky_MCP_joint"
        multiplier="1"
        offset="0" />
  </joint>
  <link
    name="right_arm_base_link">
    <inertial>
      <origin
        xyz="-0.00026981 -0.034587 -3.669E-08"
        rpy="0 0 0" />
      <mass
        value="1.48" />
      <inertia
        ixx="0.0010298"
        ixy="5.2194E-06"
        ixz="1.2188E-07"
        iyy="0.0014076"
        iyz="5.1015E-09"
        izz="0.0010201" />
    </inertial>
    <visual>
      <origin
        xyz="0 0 0"
        rpy="0 0 0" />
      <geometry>
        <mesh
          filename="package://mobiman/urdf/r1_pro_with_hand/meshes/right_arm_base_link.STL" />
      </geometry>
      <material
        name="">
        <color
          rgba="0.82353 0.82353 1 1" />
      </material>
    </visual>
    <collision>
      <origin
        xyz="0 0 0"
        rpy="0 0 0" />
      <geometry>
        <mesh
          filename="package://mobiman/urdf/r1_pro_with_hand/meshes/right_arm_base_link.STL" />
      </geometry>
    </collision>
  </link>
  <joint
    name="right_arm_base_joint"
    type="fixed">
    <origin
      xyz="-0.00048706 -0.097236 0.30302"
      rpy="0 0 0" />
    <parent
      link="torso_link4" />
    <child
      link="right_arm_base_link" />
    <axis
      xyz="0 0 0" />
  </joint>
  <link
    name="right_arm_link1">
    <inertial>
      <origin
        xyz="-0.00042261 -0.074132 7.8365E-05"
        rpy="0 0 0" />
      <mass
        value="1.135" />
      <inertia
        ixx="0.00061603"
        ixy="-1.1635E-06"
        ixz="6.9785E-07"
        iyy="0.00030259"
        iyz="6.2359E-07"
        izz="0.00047135" />
    </inertial>
    <visual>
      <origin
        xyz="0 0 0"
        rpy="0 0 0" />
      <geometry>
        <mesh
          filename="package://mobiman/urdf/r1_pro_with_hand/meshes/right_arm_link1.STL" />
      </geometry>
      <material
        name="">
        <color
          rgba="0.82353 0.82353 1 1" />
      </material>
    </visual>
    <collision>
      <origin
        xyz="0 0 0"
        rpy="0 0 0" />
      <geometry>
        <mesh
          filename="package://mobiman/urdf/r1_pro_with_hand/meshes/right_arm_link1.STL" />
      </geometry>
    </collision>
  </link>
  <joint
    name="right_arm_joint1"
    type="revolute">
    <origin
      xyz="0 -0.0735 0"
      rpy="0 0 0" />
    <parent
      link="right_arm_base_link" />
    <child
      link="right_arm_link1" />
    <axis
      xyz="0 1 0" />
    <limit
      lower="-4.4506"
      upper="1.3090"
      effort="55"
      velocity="7.1209" />
  </joint>
  <link
    name="right_arm_link2">
    <inertial>
      <origin
        xyz="-0.022361 0.0049527 -0.032732"
        rpy="0 0 0" />
      <mass
        value="0.92" />
      <inertia
        ixx="0.00038179"
        ixy="2.6532E-07"
        ixz="-3.6367E-06"
        iyy="0.00034188"
        iyz="-8.4407E-06"
        izz="0.00032895" />
    </inertial>
    <visual>
      <origin
        xyz="0 0 0"
        rpy="0 0 0" />
      <geometry>
        <mesh
          filename="package://mobiman/urdf/r1_pro_with_hand/meshes/right_arm_link2.STL" />
      </geometry>
      <material
        name="">
        <color
          rgba="0.82353 0.82353 1 1" />
      </material>
    </visual>
    <collision>
      <origin
        xyz="0 0 0"
        rpy="0 0 0" />
      <geometry>
        <mesh
          filename="package://mobiman/urdf/r1_pro_with_hand/meshes/right_arm_link2.STL" />
      </geometry>
    </collision>
  </link>
  <joint
    name="right_arm_joint2"
    type="revolute">
    <origin
      xyz="0.023988 -0.081265 0"
      rpy="0 0 0" />
    <parent
      link="right_arm_link1" />
    <child
      link="right_arm_link2" />
    <axis
      xyz="1 0 0" />
    <limit
      lower="-3.1416"
      upper="0.1745"
      effort="55"
      velocity="7.1209" />
  </joint>
  <link
    name="right_arm_link3">
    <inertial>
      <origin
        xyz="0.0053839 -0.00087109 -0.11261"
        rpy="0 0 0" />
      <mass
        value="1.245" />
      <inertia
        ixx="0.00072336"
        ixy="-3.3628E-06"
        ixz="-0.00012821"
        iyy="0.00073854"
        iyz="-8.3749E-06"
        izz="0.00037348" />
    </inertial>
    <visual>
      <origin
        xyz="0 0 0"
        rpy="0 0 0" />
      <geometry>
        <mesh
          filename="package://mobiman/urdf/r1_pro_with_hand/meshes/right_arm_link3.STL" />
      </geometry>
      <material
        name="">
        <color
          rgba="0.82353 0.82353 1 1" />
      </material>
    </visual>
    <collision>
      <origin
        xyz="0 0 0"
        rpy="0 0 0" />
      <geometry>
        <mesh
          filename="package://mobiman/urdf/r1_pro_with_hand/meshes/right_arm_link3.STL" />
      </geometry>
    </collision>
  </link>
  <joint
    name="right_arm_joint3"
    type="revolute">
    <origin
      xyz="-0.023988 0 -0.1155"
      rpy="0 0 0" />
    <parent
      link="right_arm_link2" />
    <child
      link="right_arm_link3" />
    <axis
      xyz="0 0 1" />
    <limit
      lower="-2.356196"
      upper="2.356196"
      effort="25"
      velocity="8.3776" />
  </joint>
  <link
    name="right_arm_link4">
    <inertial>
      <origin
        xyz="-0.00058877 -0.035687 -0.057422"
        rpy="0 0 0" />
      <mass
        value="0.827" />
      <inertia
        ixx="0.00016157"
        ixy="7.8184E-08"
        ixz="3.5925E-06"
        iyy="0.00022024"
        iyz="1.4211E-06"
        izz="0.00012683" />
    </inertial>
    <visual>
      <origin
        xyz="0 0 0"
        rpy="0 0 0" />
      <geometry>
        <mesh
          filename="package://mobiman/urdf/r1_pro_with_hand/meshes/right_arm_link4.STL" />
      </geometry>
      <material
        name="">
        <color
          rgba="0.82353 0.82353 1 1" />
      </material>
    </visual>
    <collision>
      <origin
        xyz="0 0 0"
        rpy="0 0 0" />
      <geometry>
        <mesh
          filename="package://mobiman/urdf/r1_pro_with_hand/meshes/right_arm_link4.STL" />
      </geometry>
    </collision>
  </link>
  <joint
    name="right_arm_joint4"
    type="revolute">
    <origin
      xyz="0 0.035058 -0.1945"
      rpy="0 0 0" />
    <parent
      link="right_arm_link3" />
    <child
      link="right_arm_link4" />
    <axis
      xyz="0 1 0" />
    <limit
      lower="-1.7453"
      upper="0.3491"
      effort="25"
      velocity="8.3776" />
  </joint>
  <link
    name="right_arm_link5">
    <inertial>
      <origin
        xyz="-2.2815E-07 0.0031762 -0.07334"
        rpy="0 0 0" />
      <mass
        value="0.63" />
      <inertia
        ixx="0.00069134"
        ixy="1.4191E-08"
        ixz="3.837E-09"
        iyy="0.00065644"
        iyz="5.1952E-05"
        izz="0.00031157" />
    </inertial>
    <visual>
      <origin
        xyz="0 0 0"
        rpy="0 0 0" />
      <geometry>
        <mesh
          filename="package://mobiman/urdf/r1_pro_with_hand/meshes/right_arm_link5.STL" />
      </geometry>
      <material
        name="">
        <color
          rgba="0.82353 0.82353 1 1" />
      </material>
    </visual>
    <collision>
      <origin
        xyz="0 0 0"
        rpy="0 0 0" />
      <geometry>
        <mesh
          filename="package://mobiman/urdf/r1_pro_with_hand/meshes/right_arm_link5.STL" />
      </geometry>
    </collision>
  </link>
  <joint
    name="right_arm_joint5"
    type="revolute">
    <origin
      xyz="0 -0.035058 -0.095"
      rpy="0 0 0" />
    <parent
      link="right_arm_link4" />
    <child
      link="right_arm_link5" />
    <axis
      xyz="0 0 1" />
    <limit
      lower="-2.356196"
      upper="2.356196"
      effort="18"
      velocity="10.4720" />
  </joint>
  <link
    name="right_arm_link6">
    <inertial>
      <origin
        xyz="0.0017914 -0.027486 0.00025485"
        rpy="0 0 0" />
      <mass
        value="0.527" />
      <inertia
        ixx="8.5442E-05"
        ixy="1.5357E-07"
        ixz="8.3693E-07"
        iyy="8.1185E-05"
        iyz="2.2221E-08"
        izz="8.2736E-05" />
    </inertial>
    <visual>
      <origin
        xyz="0 0 0"
        rpy="0 0 0" />
      <geometry>
        <mesh
          filename="package://mobiman/urdf/r1_pro_with_hand/meshes/right_arm_link6.STL" />
      </geometry>
      <material
        name="">
        <color
          rgba="0.82353 0.82353 1 1" />
      </material>
    </visual>
    <collision>
      <origin
        xyz="0 0 0"
        rpy="0 0 0" />
      <geometry>
        <mesh
          filename="package://mobiman/urdf/r1_pro_with_hand/meshes/right_arm_link6.STL" />
      </geometry>
    </collision>
  </link>
  <joint
    name="right_arm_joint6"
    type="revolute">
    <origin
      xyz="0 0.028001 -0.16305"
      rpy="0 0 0" />
    <parent
      link="right_arm_link5" />
    <child
      link="right_arm_link6" />
    <axis
      xyz="0 1 0" />
    <limit
      lower="-1.047198"
      upper="1.047198"
      effort="18"
      velocity="10.4720" />
  </joint>
  <link
    name="right_arm_link7">
    <inertial>
      <origin
        xyz="-0.022945 2.2938E-07 -0.056523"
        rpy="0 0 0" />
      <mass
        value="0.185" />
      <inertia
        ixx="7.8535E-05"
        ixy="-9.5509E-10"
        ixz="-2.8712E-05"
        iyy="9.467E-05"
        iyz="9.104E-11"
        izz="6.1128E-05" />
    </inertial>
    <visual>
      <origin
        xyz="0 0 0"
        rpy="0 0 0" />
      <geometry>
        <mesh
          filename="package://mobiman/urdf/r1_pro_with_hand/meshes/right_arm_link7.STL" />
      </geometry>
      <material
        name="">
        <color
          rgba="0.82353 0.82353 1 1" />
      </material>
    </visual>
    <collision>
      <origin
        xyz="0 0 0"
        rpy="0 0 0" />
      <geometry>
        <mesh
          filename="package://mobiman/urdf/r1_pro_with_hand/meshes/right_arm_link7.STL" />
      </geometry>
    </collision>
  </link>
  <joint
    name="right_arm_joint7"
    type="revolute">
    <origin
      xyz="0.0295 -0.028001 0"
      rpy="0 0 0" />
    <parent
      link="right_arm_link6" />
    <child
      link="right_arm_link7" />
    <axis
      xyz="1 0 0" />
    <limit
      lower="-1.5708"
      upper="1.5708"
      effort="18"
      velocity="10.4720" />
  </joint>
  <link
    name="R_hand_base_link">
    <inertial>
      <origin
        xyz="-0.0010891 0.00078822 -0.025728"
        rpy="0 0 0" />
      <mass
        value="0.052426" />
      <inertia
        ixx="2.3122E-05"
        ixy="2.1788E-07"
        ixz="-7.3376E-07"
        iyy="2.707E-05"
        iyz="8.4793E-07"
        izz="2.4809E-05" />
    </inertial>
    <visual>
      <origin
        xyz="0 0 0"
        rpy="0 0 0" />
      <geometry>
        <mesh
          filename="package://mobiman/urdf/r1_pro_with_hand/meshes/R_hand_base_link.STL" />
      </geometry>
      <material
        name="">
        <color
          rgba="0.89804 0.91373 0.92549 1" />
      </material>
    </visual>
    <collision>
      <origin
        xyz="0 0 0"
        rpy="0 0 0" />
      <geometry>
        <mesh
          filename="package://mobiman/urdf/r1_pro_with_hand/meshes/R_hand_base_link.STL" />
      </geometry>
    </collision>
  </link>
  <joint
    name="R_hand_base_joint"
    type="fixed">
    <origin
      xyz="-0.0295 0 -0.084"
      rpy="0 0 0" />
    <parent
      link="right_arm_link7" />
    <child
      link="R_hand_base_link" />
    <axis
      xyz="0 0 0" />
  </joint>
  <link
    name="R_hand_palm_link">
    <inertial>
      <origin
        xyz="-0.0023272 -0.02129 -0.002334"
        rpy="0 0 0" />
      <mass
        value="0.061425" />
      <inertia
        ixx="2.6378E-05"
        ixy="5.4943E-09"
        ixz="-8.4675E-07"
        iyy="3.4821E-05"
        iyz="6.33E-07"
        izz="1.0235E-05" />
    </inertial>
    <visual>
      <origin
        xyz="0 0 0"
        rpy="0 0 0" />
      <geometry>
        <mesh
          filename="package://mobiman/urdf/r1_pro_with_hand/meshes/R_hand_palm_link.STL" />
      </geometry>
      <material
        name="">
        <color
          rgba="0.79216 0.81961 0.93333 1" />
      </material>
    </visual>
    <collision>
      <origin
        xyz="0 0 0"
        rpy="0 0 0" />
      <geometry>
        <mesh
          filename="package://mobiman/urdf/r1_pro_with_hand/meshes/R_hand_palm_link.STL" />
      </geometry>
    </collision>
  </link>
  <joint
    name="R_hand_palm_joint"
    type="fixed">
    <origin
      xyz="0.00048677 0.020961 -0.082692"
      rpy="0 0 0" />
    <parent
      link="R_hand_base_link" />
    <child
      link="R_hand_palm_link" />
    <axis
      xyz="0 0 0" />
  </joint>
  <link
    name="R_thumb_proximal_base">
    <inertial>
      <origin
        xyz="0.0035776 0.0025114 -0.00066949"
        rpy="0 0 0" />
      <mass
        value="0.001719" />
      <inertia
        ixx="6.4582E-08"
        ixy="-1.4958E-08"
        ixz="2.0343E-09"
        iyy="5.5836E-08"
        iyz="2.2326E-09"
        izz="6.0112E-08" />
    </inertial>
    <visual>
      <origin
        xyz="0 0 0"
        rpy="0 0 0" />
      <geometry>
        <mesh
          filename="package://mobiman/urdf/r1_pro_with_hand/meshes/R_thumb_proximal_base.STL" />
      </geometry>
      <material
        name="">
        <color
          rgba="0.82745 0.83922 0.82745 1" />
      </material>
    </visual>
    <collision>
      <origin
        xyz="0 0 0"
        rpy="0 0 0" />
      <geometry>
        <mesh
          filename="package://mobiman/urdf/r1_pro_with_hand/meshes/R_thumb_proximal_base.STL" />
      </geometry>
    </collision>
  </link>
  <joint
    name="R_thumb_MCP_joint1"
    type="revolute">
    <origin
      xyz="0.02045 0.016961 -0.0606"
      rpy="0 0 0" />
    <parent
      link="R_hand_base_link" />
    <child
      link="R_thumb_proximal_base" />
    <axis
      xyz="0 0 1" />
    <limit
      lower="0"
      upper="1.1"
      effort="50"
      velocity="1" />
  </joint>
  <link
    name="R_thumb_proximal">
    <inertial>
      <origin
        xyz="-2.9202E-05 0.021737 -0.014506"
        rpy="0 0 0" />
      <mass
        value="0.0067546" />
      <inertia
        ixx="2.7612E-06"
        ixy="-3.6847E-10"
        ixz="1.4288E-09"
        iyy="1.6106E-06"
        iyz="7.4838E-07"
        izz="1.6743E-06" />
    </inertial>
    <visual>
      <origin
        xyz="0 0 0"
        rpy="0 0 0" />
      <geometry>
        <mesh
          filename="package://mobiman/urdf/r1_pro_with_hand/meshes/R_thumb_proximal.STL" />
      </geometry>
      <material
        name="">
        <color
          rgba="0.79216 0.81961 0.92941 1" />
      </material>
    </visual>
    <collision>
      <origin
        xyz="0 0 0"
        rpy="0 0 0" />
      <geometry>
        <mesh
          filename="package://mobiman/urdf/r1_pro_with_hand/meshes/R_thumb_proximal.STL" />
      </geometry>
    </collision>
  </link>
  <joint
    name="R_thumb_MCP_joint2"
    type="revolute">
    <origin
      xyz="0.0086233 0.0076085 0.00075"
      rpy="0 0 -0.84784" />
    <parent
      link="R_thumb_proximal_base" />
    <child
      link="R_thumb_proximal" />
    <axis
      xyz="-1 0 0" />
    <limit
      lower="0"
      upper="0.5"
      effort="50"
      velocity="1" />
  </joint>
  <link
    name="R_thumb_intermediate">
    <inertial>
      <origin
        xyz="-9.1769E-05 0.0094763 0.000146"
        rpy="0 0 0" />
      <mass
        value="0.0040782" />
      <inertia
        ixx="4.5871E-07"
        ixy="7.8089E-11"
        ixz="1.0957E-10"
        iyy="3.9195E-07"
        iyz="8.953E-08"
        izz="3.0896E-07" />
    </inertial>
    <visual>
      <origin
        xyz="0 0 0"
        rpy="0 0 0" />
      <geometry>
        <mesh
          filename="package://mobiman/urdf/r1_pro_with_hand/meshes/R_thumb_intermediate.STL" />
      </geometry>
      <material
        name="">
        <color
          rgba="1 1 1 1" />
      </material>
    </visual>
    <collision>
      <origin
        xyz="0 0 0"
        rpy="0 0 0" />
      <geometry>
        <mesh
          filename="package://mobiman/urdf/r1_pro_with_hand/meshes/R_thumb_intermediate.STL" />
      </geometry>
    </collision>
  </link>
  <joint
    name="R_thumb_PIP_joint"
    type="revolute">
    <origin
      xyz="0.0001 0.042177 -0.03684"
      rpy="0 0 0" />
    <parent
      link="R_thumb_proximal" />
    <child
      link="R_thumb_intermediate" />
    <axis
      xyz="-1 0 0" />
    <limit
      lower="0"
      upper="1"
      effort="50"
      velocity="1" />
    <mimic 
        joint="R_thumb_MCP_joint2"
        multiplier="1.6"
        offset="0" />
  </joint>
  <link
    name="R_thumb_distal">
    <inertial>
      <origin
        xyz="-3.3928E-06 0.0085726 -0.0063011"
        rpy="0 0 0" />
      <mass
        value="0.0033086" />
      <inertia
        ixx="1.9617E-07"
        ixy="-7.4626E-11"
        ixz="1.3466E-10"
        iyy="1.5084E-07"
        iyz="5.3155E-08"
        izz="1.2143E-07" />
    </inertial>
    <visual>
      <origin
        xyz="0 0 0"
        rpy="0 0 0" />
      <geometry>
        <mesh
          filename="package://mobiman/urdf/r1_pro_with_hand/meshes/R_thumb_distal.STL" />
      </geometry>
      <material
        name="">
        <color
          rgba="1 1 1 1" />
      </material>
    </visual>
    <collision>
      <origin
        xyz="0 0 0"
        rpy="0 0 0" />
      <geometry>
        <mesh
          filename="package://mobiman/urdf/r1_pro_with_hand/meshes/R_thumb_distal.STL" />
      </geometry>
    </collision>
  </link>
  <joint
    name="R_thumb_DIP_joint"
    type="revolute">
    <origin
      xyz="-0.0001 0.018862 -0.012545"
      rpy="0 0 0" />
    <parent
      link="R_thumb_intermediate" />
    <child
      link="R_thumb_distal" />
    <axis
      xyz="-1 0 0" />
    <limit
      lower="0"
      upper="1.2"
      effort="50"
      velocity="1" />
    <mimic 
        joint="R_thumb_MCP_joint2"
        multiplier="2.4"
        offset="0" />
  </joint>
  <link
    name="R_index_proximal">
    <inertial>
      <origin
        xyz="5.2077E-08 -0.00063565 -0.012457"
        rpy="0 0 0" />
      <mass
        value="0.004404" />
      <inertia
        ixx="6.5596E-07"
        ixy="-1.1211E-12"
        ixz="-5.0386E-13"
        iyy="6.2552E-07"
        iyz="6.4014E-09"
        izz="2.1898E-07" />
    </inertial>
    <visual>
      <origin
        xyz="0 0 0"
        rpy="0 0 0" />
      <geometry>
        <mesh
          filename="package://mobiman/urdf/r1_pro_with_hand/meshes/R_index_proximal.STL" />
      </geometry>
      <material
        name="">
        <color
          rgba="0.79216 0.81961 0.92941 1" />
      </material>
    </visual>
    <collision>
      <origin
        xyz="0 0 0"
        rpy="0 0 0" />
      <geometry>
        <mesh
          filename="package://mobiman/urdf/r1_pro_with_hand/meshes/R_index_proximal.STL" />
      </geometry>
    </collision>
  </link>
  <joint
    name="R_index_MCP_joint"
    type="revolute">
    <origin
      xyz="0.026271 -0.0002841 -0.13674"
      rpy="0 -0.034905 0" />
    <parent
      link="R_hand_base_link" />
    <child
      link="R_index_proximal" />
    <axis
      xyz="1 0 0" />
    <limit
      lower="0"
      upper="1.7"
      effort="50"
      velocity="1" />
  </joint>
  <link
    name="R_index_distal">
    <inertial>
      <origin
        xyz="-6.195E-08 -0.0018889 -0.019485"
        rpy="0 0 0" />
      <mass
        value="0.0046337" />
      <inertia
        ixx="7.8445E-07"
        ixy="-2.6472E-12"
        ixz="-1.0782E-12"
        iyy="7.6018E-07"
        iyz="1.029E-07"
        izz="9.9074E-08" />
    </inertial>
    <visual>
      <origin
        xyz="0 0 0"
        rpy="0 0 0" />
      <geometry>
        <mesh
          filename="package://mobiman/urdf/r1_pro_with_hand/meshes/R_index_distal.STL" />
      </geometry>
      <material
        name="">
        <color
          rgba="1 1 1 1" />
      </material>
    </visual>
    <collision>
      <origin
        xyz="0 0 0"
        rpy="0 0 0" />
      <geometry>
        <mesh
          filename="package://mobiman/urdf/r1_pro_with_hand/meshes/R_index_distal.STL" />
      </geometry>
    </collision>
  </link>
  <joint
    name="R_index_DIP_joint"
    type="revolute">
    <origin
      xyz="0 0.0027966 -0.03201"
      rpy="0 0 0" />
    <parent
      link="R_index_proximal" />
    <child
      link="R_index_distal" />
    <axis
      xyz="1 0 0" />
    <limit
      lower="0"
      upper="1.6"
      effort="50"
      velocity="1" />
    <mimic 
        joint="R_index_MCP_joint"
        multiplier="1"
        offset="0" />
  </joint>
  <link
    name="R_middle_proximal">
    <inertial>
      <origin
        xyz="3.2881E-08 -0.00063558 -0.012457"
        rpy="0 0 0" />
      <mass
        value="0.004404" />
      <inertia
        ixx="6.5597E-07"
        ixy="-3.051E-13"
        ixz="-8.1407E-14"
        iyy="6.2552E-07"
        iyz="6.4009E-09"
        izz="2.1898E-07" />
    </inertial>
    <visual>
      <origin
        xyz="0 0 0"
        rpy="0 0 0" />
      <geometry>
        <mesh
          filename="package://mobiman/urdf/r1_pro_with_hand/meshes/R_middle_proximal.STL" />
      </geometry>
      <material
        name="">
        <color
          rgba="0.79216 0.81961 0.92941 1" />
      </material>
    </visual>
    <collision>
      <origin
        xyz="0 0 0"
        rpy="0 0 0" />
      <geometry>
        <mesh
          filename="package://mobiman/urdf/r1_pro_with_hand/meshes/R_middle_proximal.STL" />
      </geometry>
    </collision>
  </link>
  <joint
    name="R_middle_MCP_joint"
    type="revolute">
    <origin
      xyz="0.00695 -0.00028401 -0.1371"
      rpy="0 0 0" />
    <parent
      link="R_hand_base_link" />
    <child
      link="R_middle_proximal" />
    <axis
      xyz="1 0 0" />
    <limit
      lower="0"
      upper="1.68"
      effort="50"
      velocity="1" />
  </joint>
  <link
    name="R_middle_distal">
    <inertial>
      <origin
        xyz="-1.1832E-07 -0.0015037 -0.020979"
        rpy="0 0 0" />
      <mass
        value="0.0050034" />
      <inertia
        ixx="9.6839E-07"
        ixy="-2.1196E-12"
        ixz="2.6308E-13"
        iyy="9.3771E-07"
        iyz="1.3276E-07"
        izz="1.1122E-07" />
    </inertial>
    <visual>
      <origin
        xyz="0 0 0"
        rpy="0 0 0" />
      <geometry>
        <mesh
          filename="package://mobiman/urdf/r1_pro_with_hand/meshes/R_middle_distal.STL" />
      </geometry>
      <material
        name="">
        <color
          rgba="1 1 1 1" />
      </material>
    </visual>
    <collision>
      <origin
        xyz="0 0 0"
        rpy="0 0 0" />
      <geometry>
        <mesh
          filename="package://mobiman/urdf/r1_pro_with_hand/meshes/R_middle_distal.STL" />
      </geometry>
    </collision>
  </link>
  <joint
    name="R_middle_DIP_joint"
    type="revolute">
    <origin
      xyz="0 0.0027966 -0.03201"
      rpy="0 0 0" />
    <parent
      link="R_middle_proximal" />
    <child
      link="R_middle_distal" />
    <axis
      xyz="1 0 0" />
    <limit
      lower="0"
      upper="1.6"
      effort="50"
      velocity="1" />
    <mimic 
        joint="R_middle_MCP_joint"
        multiplier="1"
        offset="0" />
  </joint>
  <link
    name="R_ring_proximal">
    <inertial>
      <origin
        xyz="1.2273E-08 -0.00063564 -0.012457"
        rpy="0 0 0" />
      <mass
        value="0.004404" />
      <inertia
        ixx="6.5597E-07"
        ixy="5.0504E-13"
        ixz="4.014E-13"
        iyy="6.2552E-07"
        iyz="6.4015E-09"
        izz="2.1898E-07" />
    </inertial>
    <visual>
      <origin
        xyz="0 0 0"
        rpy="0 0 0" />
      <geometry>
        <mesh
          filename="package://mobiman/urdf/r1_pro_with_hand/meshes/R_ring_proximal.STL" />
      </geometry>
      <material
        name="">
        <color
          rgba="0.79216 0.81961 0.92941 1" />
      </material>
    </visual>
    <collision>
      <origin
        xyz="0 0 0"
        rpy="0 0 0" />
      <geometry>
        <mesh
          filename="package://mobiman/urdf/r1_pro_with_hand/meshes/R_ring_proximal.STL" />
      </geometry>
    </collision>
  </link>
  <joint
    name="R_ring_MCP_joint"
    type="revolute">
    <origin
      xyz="-0.012279 -0.00028393 -0.1366"
      rpy="0 0.052362 0" />
    <parent
      link="R_hand_base_link" />
    <child
      link="R_ring_proximal" />
    <axis
      xyz="1 0 0" />
    <limit
      lower="0"
      upper="1.7"
      effort="50"
      velocity="1" />
  </joint>
  <link
    name="R_ring_distal">
    <inertial>
      <origin
        xyz="-6.1891E-08 -0.0018889 -0.019485"
        rpy="0 0 0" />
      <mass
        value="0.0046337" />
      <inertia
        ixx="7.8444E-07"
        ixy="-2.468E-12"
        ixz="-1.5433E-12"
        iyy="7.6018E-07"
        iyz="1.029E-07"
        izz="9.9073E-08" />
    </inertial>
    <visual>
      <origin
        xyz="0 0 0"
        rpy="0 0 0" />
      <geometry>
        <mesh
          filename="package://mobiman/urdf/r1_pro_with_hand/meshes/R_ring_distal.STL" />
      </geometry>
      <material
        name="">
        <color
          rgba="1 1 1 1" />
      </material>
    </visual>
    <collision>
      <origin
        xyz="0 0 0"
        rpy="0 0 0" />
      <geometry>
        <mesh
          filename="package://mobiman/urdf/r1_pro_with_hand/meshes/R_ring_distal.STL" />
      </geometry>
    </collision>
  </link>
  <joint
    name="R_ring_DIP_joint"
    type="revolute">
    <origin
      xyz="0 0.0027966 -0.03201"
      rpy="0 0 0" />
    <parent
      link="R_ring_proximal" />
    <child
      link="R_ring_distal" />
    <axis
      xyz="1 0 0" />
    <limit
      lower="0"
      upper="1.6"
      effort="50"
      velocity="1" />
    <mimic 
        joint="R_ring_MCP_joint"
        multiplier="1"
        offset="0" />
  </joint>
  <link
    name="R_pinky_proximal">
    <inertial>
      <origin
        xyz="1.0964E-08 -0.00063564 -0.012457"
        rpy="0 0 0" />
      <mass
        value="0.004404" />
      <inertia
        ixx="6.5597E-07"
        ixy="4.3193E-13"
        ixz="2.6692E-13"
        iyy="6.2552E-07"
        iyz="6.4015E-09"
        izz="2.1898E-07" />
    </inertial>
    <visual>
      <origin
        xyz="0 0 0"
        rpy="0 0 0" />
      <geometry>
        <mesh
          filename="package://mobiman/urdf/r1_pro_with_hand/meshes/R_pinky_proximal.STL" />
      </geometry>
      <material
        name="">
        <color
          rgba="0.79216 0.81961 0.92941 1" />
      </material>
    </visual>
    <collision>
      <origin
        xyz="0 0 0"
        rpy="0 0 0" />
      <geometry>
        <mesh
          filename="package://mobiman/urdf/r1_pro_with_hand/meshes/R_pinky_proximal.STL" />
      </geometry>
    </collision>
  </link>
  <joint
    name="R_pinky_MCP_joint"
    type="revolute">
    <origin
      xyz="-0.031455 -0.00028384 -0.13509"
      rpy="0 0.10472 0" />
    <parent
      link="R_hand_base_link" />
    <child
      link="R_pinky_proximal" />
    <axis
      xyz="1 0 0" />
    <limit
      lower="0"
      upper="1.7"
      effort="50"
      velocity="1" />
  </joint>
  <link
    name="R_pinky_distal">
    <inertial>
      <origin
        xyz="-3.8189E-07 -0.0022677 -0.015978"
        rpy="0 0 0" />
      <mass
        value="0.0037038" />
      <inertia
        ixx="4.4337E-07"
        ixy="-6.2949E-12"
        ixz="1.7422E-12"
        iyy="4.2989E-07"
        iyz="5.6052E-08"
        izz="7.2995E-08" />
    </inertial>
    <visual>
      <origin
        xyz="0 0 0"
        rpy="0 0 0" />
      <geometry>
        <mesh
          filename="package://mobiman/urdf/r1_pro_with_hand/meshes/R_pinky_distal.STL" />
      </geometry>
      <material
        name="">
        <color
          rgba="1 1 1 1" />
      </material>
    </visual>
    <collision>
      <origin
        xyz="0 0 0"
        rpy="0 0 0" />
      <geometry>
        <mesh
          filename="package://mobiman/urdf/r1_pro_with_hand/meshes/R_pinky_distal.STL" />
      </geometry>
    </collision>
  </link>
  <joint
    name="R_pinky_DIP_joint"
    type="revolute">
    <origin
      xyz="0 0.0027967 -0.03201"
      rpy="0 0 0" />
    <parent
      link="R_pinky_proximal" />
    <child
      link="R_pinky_distal" />
    <axis
      xyz="1 0 0" />
    <limit
      lower="0"
      upper="1.6"
      effort="50"
      velocity="1" />
    <mimic 
        joint="R_pinky_MCP_joint"
        multiplier="1"
        offset="0" />
  </joint>
</robot>